<?xml version="1.0" encoding="utf-8"?>
<robot xmlns:xacro="http://www.ros.org/wiki/xacro"
  name="biped_v4">
  <!-- WORLD -->
  <link name="world"/>

  <!-- BASE LINK -->
  <joint name="base_joint" type="fixed">
    <parent link="world"/>
    <child link="base_link"/>
    <origin rpy="0 0 0" xyz="0.0 0.0 1.0"/>
  </joint>
  
  <link
    name="base_link">
    <inertial>
      <origin
        xyz="-1.1257E-18 1.209E-17 0.0040839"
        rpy="0 0 0" />
      <mass
        value="0.018" />
      <inertia
        ixx="8.1069E-06"
        ixy="3.6409E-21"
        ixz="-1.5116E-21"
        iyy="8.5785E-06"
        iyz="1.6877E-21"
        izz="1.6342E-05" />
    </inertial>
    <visual>
      <origin
        xyz="0 0 0"
        rpy="0 0 0" />
      <geometry>
        <mesh
          filename="file://$(find robot_bringup)/meshes/base_link.STL" />
      </geometry>
      <material
        name="">
        <color
          rgba="0.79216 0.81961 0.93333 1" />
      </material>
    </visual>
    <collision>
      <origin
        xyz="0 0 0"
        rpy="0 0 0" />
      <geometry>
        <mesh
          filename="file://$(find robot_bringup)/meshes/base_link.STL" />
      </geometry>
    </collision>
  </link>
  <link
    name="fix_leftlegtobaselink">
    <inertial>
      <origin
        xyz="3.1196E-09 -0.059316 0.0042205"
        rpy="0 0 0" />
      <mass
        value="0.028" />
      <inertia
        ixx="8.1588E-06"
        ixy="-1.3085E-13"
        ixz="-4.33E-11"
        iyy="7.7241E-06"
        iyz="-9.9424E-07"
        izz="8.6259E-06" />
    </inertial>
    <visual>
      <origin
        xyz="0 0 0"
        rpy="0 0 0" />
      <geometry>
        <mesh
          filename="file://$(find robot_bringup)/meshes/fix_leftlegtobaselink.STL" />
      </geometry>
      <material
        name="">
        <color
          rgba="0.79216 0.81961 0.93333 1" />
      </material>
    </visual>
    <collision>
      <origin
        xyz="0 0 0"
        rpy="0 0 0" />
      <geometry>
        <mesh
          filename="file://$(find robot_bringup)/meshes/fix_leftlegtobaselink.STL" />
      </geometry>
    </collision>
  </link>
  <joint
    name="leftlegtobaselink"
    type="fixed">
    <origin
      xyz="0 0 0"
      rpy="0 0 0" />
    <parent
      link="base_link" />
    <child
      link="fix_leftlegtobaselink" />
    <axis
      xyz="0 0 0" />
  </joint>
  <link
    name="fix_lefthip1towaist">
    <inertial>
      <origin
        xyz="-0.00081105 -0.082311 -0.024125"
        rpy="0 0 0" />
      <mass
        value="0.08" />
      <inertia
        ixx="1.0361E-05"
        ixy="-2.2331E-07"
        ixz="-2.3381E-17"
        iyy="6.7254E-06"
        iyz="-2.8598E-14"
        izz="1.1542E-05" />
    </inertial>
    <visual>
      <origin
        xyz="0 0 0"
        rpy="0 0 0" />
      <geometry>
        <mesh
          filename="file://$(find robot_bringup)/meshes/fix_lefthip1towaist.STL" />
      </geometry>
      <material
        name="">
        <color
          rgba="0.79216 0.81961 0.93333 1" />
      </material>
    </visual>
    <collision>
      <origin
        xyz="0 0 0"
        rpy="0 0 0" />
      <geometry>
        <mesh
          filename="file://$(find robot_bringup)/meshes/fix_lefthip1towaist.STL" />
      </geometry>
    </collision>
  </link>
  <joint
    name="lefthip1towaist"
    type="fixed">
    <origin
      xyz="0 0 0"
      rpy="0 0 0" />
    <parent
      link="fix_leftlegtobaselink" />
    <child
      link="fix_lefthip1towaist" />
    <axis
      xyz="0 0 0" />
  </joint>
  <link
    name="revolute_left_femur1_1">
    <inertial>
      <origin
        xyz="0.019235 -1.3878E-17 0.026145"
        rpy="0 0 0" />
      <mass
        value="0.016" />
      <inertia
        ixx="4.4847E-06"
        ixy="-3.2515E-22"
        ixz="2.5399E-07"
        iyy="5.4156E-06"
        iyz="6.6534E-22"
        izz="1.6499E-06" />
    </inertial>
    <visual>
      <origin
        xyz="0 0 0"
        rpy="0 0 0" />
      <geometry>
        <mesh
          filename="file://$(find robot_bringup)/meshes/revolute_left_femur1_1.STL" />
      </geometry>
      <material
        name="">
        <color
          rgba="1 1 1 1" />
      </material>
    </visual>
    <collision>
      <origin
        xyz="0 0 0"
        rpy="0 0 0" />
      <geometry>
        <mesh
          filename="file://$(find robot_bringup)/meshes/revolute_left_femur1_1.STL" />
      </geometry>
    </collision>
  </link>
  <joint
    name="left_hip1"
    type="revolute">
    <origin
      xyz="-0.0234 -0.09425 -0.024125"
      rpy="0 1.5707963267949 0" />
    <parent
      link="fix_lefthip1towaist" />
    <child
      link="revolute_left_femur1_1" />
    <axis
      xyz="0 0 -1" />
    <limit
      lower="-1.732"
      upper="1.732"
      effort="3.7"
      velocity="10" />
  </joint>
  <link
    name="fix_leftfemur1_2">
    <inertial>
      <origin
        xyz="0.048875 -0.00081105 0.021339"
        rpy="0 0 0" />
      <mass
        value="0.08" />
      <inertia
        ixx="1.1542E-05"
        ixy="-2.3396E-17"
        ixz="-2.8598E-14"
        iyy="1.0361E-05"
        iyz="-2.2331E-07"
        izz="6.7254E-06" />
    </inertial>
    <visual>
      <origin
        xyz="0 0 0"
        rpy="0 0 0" />
      <geometry>
        <mesh
          filename="file://$(find robot_bringup)/meshes/fix_leftfemur1_2.STL" />
      </geometry>
      <material
        name="">
        <color
          rgba="0.79216 0.81961 0.93333 1" />
      </material>
    </visual>
    <collision>
      <origin
        xyz="0 0 0"
        rpy="0 0 0" />
      <geometry>
        <mesh
          filename="file://$(find robot_bringup)/meshes/fix_leftfemur1_2.STL" />
      </geometry>
    </collision>
  </link>
  <joint
    name="leftfemur1_2"
    type="fixed">
    <origin
      xyz="0 0 0"
      rpy="0 0 0" />
    <parent
      link="revolute_left_femur1_1" />
    <child
      link="fix_leftfemur1_2" />
    <axis
      xyz="0 0 0" />
  </joint>
  <link
    name="revolute_left_femur2_1">
    <inertial>
      <origin
        xyz="-1.5434E-11 -0.024976 -0.025952"
        rpy="0 0 0" />
      <mass
        value="0.016" />
      <inertia
        ixx="7.0717E-06"
        ixy="-1.5333E-15"
        ixz="2.8537E-12"
        iyy="4.694E-06"
        iyz="2.9746E-07"
        izz="3.2637E-06" />
    </inertial>
    <visual>
      <origin
        xyz="0 0 0"
        rpy="0 0 0" />
      <geometry>
        <mesh
          filename="file://$(find robot_bringup)/meshes/revolute_left_femur2_1.STL" />
      </geometry>
      <material
        name="">
        <color
          rgba="1 1 1 1" />
      </material>
    </visual>
    <collision>
      <origin
        xyz="0 0 0"
        rpy="0 0 0" />
      <geometry>
        <mesh
          filename="file://$(find robot_bringup)/meshes/revolute_left_femur2_1.STL" />
      </geometry>
    </collision>
  </link>
  <joint
    name="left_hip2"
    type="revolute">
    <origin
      xyz="0.048875 -0.0234 0.00939999999999994"
      rpy="1.5707963267949 -1.5707963267949 0" />
    <parent
      link="fix_leftfemur1_2" />
    <child
      link="revolute_left_femur2_1" />
    <axis
      xyz="0 0 1" />
    <limit
      lower="-1.732"
      upper="1.732"
      effort="3.7"
      velocity="10" />
  </joint>
  <link
    name="fix_left_femur2_2">
    <inertial>
      <origin
        xyz="1.5434E-11 -0.13702 -0.025952"
        rpy="0 0 0" />
      <mass
        value="0.016" />
      <inertia
        ixx="7.0717E-06"
        ixy="-1.5333E-15"
        ixz="-2.8537E-12"
        iyy="4.694E-06"
        iyz="-2.9746E-07"
        izz="3.2637E-06" />
    </inertial>
    <visual>
      <origin
        xyz="0 0 0"
        rpy="0 0 0" />
      <geometry>
        <mesh
          filename="file://$(find robot_bringup)/meshes/fix_left_femur2_2.STL" />
      </geometry>
      <material
        name="">
        <color
          rgba="1 1 1 1" />
      </material>
    </visual>
    <collision>
      <origin
        xyz="0 0 0"
        rpy="0 0 0" />
      <geometry>
        <mesh
          filename="file://$(find robot_bringup)/meshes/fix_left_femur2_2.STL" />
      </geometry>
    </collision>
  </link>
  <joint
    name="left_femur2_2"
    type="fixed">
    <origin
      xyz="0 0 0"
      rpy="0 0 0" />
    <parent
      link="revolute_left_femur2_1" />
    <child
      link="fix_left_femur2_2" />
    <axis
      xyz="0 0 0" />
  </joint>
  <link
    name="revolute_left_knee">
    <inertial>
      <origin
        xyz="6.9714E-13 -0.011939 0.022589"
        rpy="0 0 0" />
      <mass
        value="0.08" />
      <inertia
        ixx="1.1542E-05"
        ixy="2.8598E-14"
        ixz="-2.338E-17"
        iyy="6.7254E-06"
        iyz="2.2331E-07"
        izz="1.0361E-05" />
    </inertial>
    <visual>
      <origin
        xyz="0 0 0"
        rpy="0 0 0" />
      <geometry>
        <mesh
          filename="file://$(find robot_bringup)/meshes/revolute_left_knee.STL" />
      </geometry>
      <material
        name="">
        <color
          rgba="0.79216 0.81961 0.93333 1" />
      </material>
    </visual>
    <collision>
      <origin
        xyz="0 0 0"
        rpy="0 0 0" />
      <geometry>
        <mesh
          filename="file://$(find robot_bringup)/meshes/revolute_left_knee.STL" />
      </geometry>
    </collision>
  </link>
  <joint
    name="left_knee"
    type="revolute">
    <origin
      xyz="0 -0.162 0"
      rpy="-3.14159265358979 0 -3.14159265358979" />
    <parent
      link="fix_left_femur2_2" />
    <child
      link="revolute_left_knee" />
    <axis
      xyz="0 0 1" />
    <limit
      lower="-2"
      upper="2"
      effort="5"
      velocity="10" />
  </joint>
  <link
    name="fix_lefttibia_1">
    <inertial>
      <origin
        xyz="-8.9841E-06 -0.16908 0.022299"
        rpy="0 0 0" />
      <mass
        value="0.04" />
      <inertia
        ixx="1.096E-05"
        ixy="-4.4082E-09"
        ixz="-5.2455E-09"
        iyy="6.3088E-06"
        iyz="-2.5553E-07"
        izz="9.8712E-06" />
    </inertial>
    <visual>
      <origin
        xyz="0 0 0"
        rpy="0 0 0" />
      <geometry>
        <mesh
          filename="file://$(find robot_bringup)/meshes/fix_lefttibia_1.STL" />
      </geometry>
      <material
        name="">
        <color
          rgba="0.79216 0.81961 0.93333 1" />
      </material>
    </visual>
    <collision>
      <origin
        xyz="0 0 0"
        rpy="0 0 0" />
      <geometry>
        <mesh
          filename="file://$(find robot_bringup)/meshes/fix_lefttibia_1.STL" />
      </geometry>
    </collision>
  </link>
  <joint
    name="lefttibia_1"
    type="fixed">
    <origin
      xyz="0 0 0"
      rpy="0 0 0" />
    <parent
      link="revolute_left_knee" />
    <child
      link="fix_lefttibia_1" />
    <axis
      xyz="0 0 0" />
  </joint>
  <link
    name="revolute_leftfoot">
    <inertial>
      <origin
        xyz="-0.028804 -1.6064E-07 0.033846"
        rpy="0 0 0" />
      <mass
        value="0.05" />
      <inertia
        ixx="0.00015493"
        ixy="-5.5007E-11"
        ixz="3.0716E-06"
        iyy="3.7481E-05"
        iyz="6.021E-11"
        izz="0.00012863" />
    </inertial>
    <visual>
      <origin
        xyz="0 0 0"
        rpy="0 0 0" />
      <geometry>
        <mesh
          filename="file://$(find robot_bringup)/meshes/revolute_leftfoot.STL" />
      </geometry>
      <material
        name="">
        <color
          rgba="0.79216 0.81961 0.93333 1" />
      </material>
    </visual>
    <collision>
      <origin
        xyz="0 0 0"
        rpy="0 0 0" />
      <geometry>
        <mesh
          filename="file://$(find robot_bringup)/meshes/revolute_leftfoot.STL" />
      </geometry>
    </collision>
  </link>
  <joint
    name="left_ankle"
    type="revolute">
    <origin
      xyz="0 -0.181000000000001 0.00250000000000145"
      rpy="0 0 1.57079632679489" />
    <parent
      link="fix_lefttibia_1" />
    <child
      link="revolute_leftfoot" />
    <axis
      xyz="0 0 -1" />
    <limit
      lower="-1.732"
      upper="1.732"
      effort="1.5"
      velocity="10" />
  </joint>
  <link
    name="fix_lefttibia_2">
    <inertial>
      <origin
        xyz="3.7002E-15 -0.13991 0.0234"
        rpy="0 0 0" />
      <mass
        value="0.01" />
      <inertia
        ixx="8.4456E-07"
        ixy="-7.3769E-20"
        ixz="1.598E-13"
        iyy="1.1166E-06"
        iyz="9.6352E-20"
        izz="1.4884E-06" />
    </inertial>
    <visual>
      <origin
        xyz="0 0 0"
        rpy="0 0 0" />
      <geometry>
        <mesh
          filename="file://$(find robot_bringup)/meshes/fix_lefttibia_2.STL" />
      </geometry>
      <material
        name="">
        <color
          rgba="1 1 1 1" />
      </material>
    </visual>
    <collision>
      <origin
        xyz="0 0 0"
        rpy="0 0 0" />
      <geometry>
        <mesh
          filename="file://$(find robot_bringup)/meshes/fix_lefttibia_2.STL" />
      </geometry>
    </collision>
  </link>
  <joint
    name="lefttibia_2"
    type="fixed">
    <origin
      xyz="0 0 0"
      rpy="0 0 0" />
    <parent
      link="revolute_left_knee" />
    <child
      link="fix_lefttibia_2" />
    <axis
      xyz="0 0 0" />
  </joint>
  <link
    name="fix_lefttibia_3">
    <inertial>
      <origin
        xyz="-0.00077912 -0.1234 0.026003"
        rpy="0 0 0" />
      <mass
        value="0.0008" />
      <inertia
        ixx="8.7805E-08"
        ixy="7.215E-23"
        ixz="8.4902E-09"
        iyy="1.4099E-07"
        iyz="-1.6657E-22"
        izz="6.0985E-08" />
    </inertial>
    <visual>
      <origin
        xyz="0 0 0"
        rpy="0 0 0" />
      <geometry>
        <mesh
          filename="file://$(find robot_bringup)/meshes/fix_lefttibia_3.STL" />
      </geometry>
      <material
        name="">
        <color
          rgba="0.79216 0.81961 0.93333 1" />
      </material>
    </visual>
    <collision>
      <origin
        xyz="0 0 0"
        rpy="0 0 0" />
      <geometry>
        <mesh
          filename="file://$(find robot_bringup)/meshes/fix_lefttibia_3.STL" />
      </geometry>
    </collision>
  </link>
  <joint
    name="lefttibia_3"
    type="fixed">
    <origin
      xyz="0 0 0"
      rpy="0 0 0" />
    <parent
      link="revolute_left_knee" />
    <child
      link="fix_lefttibia_3" />
    <axis
      xyz="0 0 0" />
  </joint>
  <link
    name="fix_lefttibia_4">
    <inertial>
      <origin
        xyz="-3.6429E-17 -0.0905 0.0234"
        rpy="0 0 0" />
      <mass
        value="0.007" />
      <inertia
        ixx="2.3852E-06"
        ixy="-1.1607E-21"
        ixz="1.9172E-24"
        iyy="5.7962E-08"
        iyz="1.2953E-21"
        izz="2.3852E-06" />
    </inertial>
    <visual>
      <origin
        xyz="0 0 0"
        rpy="0 0 0" />
      <geometry>
        <mesh
          filename="file://$(find robot_bringup)/meshes/fix_lefttibia_4.STL" />
      </geometry>
      <material
        name="">
        <color
          rgba="0.79216 0.81961 0.93333 1" />
      </material>
    </visual>
    <collision>
      <origin
        xyz="0 0 0"
        rpy="0 0 0" />
      <geometry>
        <mesh
          filename="file://$(find robot_bringup)/meshes/fix_lefttibia_4.STL" />
      </geometry>
    </collision>
  </link>
  <joint
    name="lefttibia_4"
    type="fixed">
    <origin
      xyz="0 0 0"
      rpy="0 0 0" />
    <parent
      link="revolute_left_knee" />
    <child
      link="fix_lefttibia_4" />
    <axis
      xyz="0 0 0" />
  </joint>
  <link
    name="fix_lefttibia_5">
    <inertial>
      <origin
        xyz="3.8181E-15 -0.04109 0.0234"
        rpy="0 0 0" />
      <mass
        value="0.01" />
      <inertia
        ixx="8.4456E-07"
        ixy="7.5351E-20"
        ixz="-1.598E-13"
        iyy="1.1166E-06"
        iyz="9.6295E-20"
        izz="1.4884E-06" />
    </inertial>
    <visual>
      <origin
        xyz="0 0 0"
        rpy="0 0 0" />
      <geometry>
        <mesh
          filename="file://$(find robot_bringup)/meshes/fix_lefttibia_5.STL" />
      </geometry>
      <material
        name="">
        <color
          rgba="1 1 1 1" />
      </material>
    </visual>
    <collision>
      <origin
        xyz="0 0 0"
        rpy="0 0 0" />
      <geometry>
        <mesh
          filename="file://$(find robot_bringup)/meshes/fix_lefttibia_5.STL" />
      </geometry>
    </collision>
  </link>
  <joint
    name="lefttibia_5"
    type="fixed">
    <origin
      xyz="0 0 0"
      rpy="0 0 0" />
    <parent
      link="revolute_left_knee" />
    <child
      link="fix_lefttibia_5" />
    <axis
      xyz="0 0 0" />
  </joint>
  <link
    name="fix_lefttibia_6">
    <inertial>
      <origin
        xyz="1.2143E-17 -0.00179 0.035364"
        rpy="0 0 0" />
      <mass
        value="0.004" />
      <inertia
        ixx="4.093E-07"
        ixy="2.5838E-23"
        ixz="2.8347E-22"
        iyy="1.0855E-06"
        iyz="1.343E-09"
        izz="7.5439E-07" />
    </inertial>
    <visual>
      <origin
        xyz="0 0 0"
        rpy="0 0 0" />
      <geometry>
        <mesh
          filename="file://$(find robot_bringup)/meshes/fix_lefttibia_6.STL" />
      </geometry>
      <material
        name="">
        <color
          rgba="0.79216 0.81961 0.93333 1" />
      </material>
    </visual>
    <collision>
      <origin
        xyz="0 0 0"
        rpy="0 0 0" />
      <geometry>
        <mesh
          filename="file://$(find robot_bringup)/meshes/fix_lefttibia_6.STL" />
      </geometry>
    </collision>
  </link>
  <joint
    name="lefttibia_6"
    type="fixed">
    <origin
      xyz="0 0 0"
      rpy="0 0 0" />
    <parent
      link="revolute_left_knee" />
    <child
      link="fix_lefttibia_6" />
    <axis
      xyz="0 0 0" />
  </joint>
  <link
    name="fix_left_femur2_3">
    <inertial>
      <origin
        xyz="2.5327E-16 -0.081 -0.0254"
        rpy="0 0 0" />
      <mass
        value="0.007" />
      <inertia
        ixx="2.3852E-06"
        ixy="3.2772E-21"
        ixz="6.7208E-24"
        iyy="5.7962E-08"
        iyz="-3.8231E-22"
        izz="2.3852E-06" />
    </inertial>
    <visual>
      <origin
        xyz="0 0 0"
        rpy="0 0 0" />
      <geometry>
        <mesh
          filename="file://$(find robot_bringup)/meshes/fix_left_femur2_3.STL" />
      </geometry>
      <material
        name="">
        <color
          rgba="0.79216 0.81961 0.93333 1" />
      </material>
    </visual>
    <collision>
      <origin
        xyz="0 0 0"
        rpy="0 0 0" />
      <geometry>
        <mesh
          filename="file://$(find robot_bringup)/meshes/fix_left_femur2_3.STL" />
      </geometry>
    </collision>
  </link>
  <joint
    name="left_femur2_3"
    type="fixed">
    <origin
      xyz="0 0 0"
      rpy="0 0 0" />
    <parent
      link="revolute_left_femur2_1" />
    <child
      link="fix_left_femur2_3" />
    <axis
      xyz="0 0 0" />
  </joint>
  <link
    name="fix_femur1_3">
    <inertial>
      <origin
        xyz="0.048875 0.0066861 0.018792"
        rpy="0 0 0" />
      <mass
        value="0.008" />
      <inertia
        ixx="1.446E-06"
        ixy="-2.2903E-22"
        ixz="6.4287E-22"
        iyy="2.2684E-06"
        iyz="3.6652E-07"
        izz="2.2752E-06" />
    </inertial>
    <visual>
      <origin
        xyz="0 0 0"
        rpy="0 0 0" />
      <geometry>
        <mesh
          filename="file://$(find robot_bringup)/meshes/fix_femur1_3.STL" />
      </geometry>
      <material
        name="">
        <color
          rgba="0.79216 0.81961 0.93333 1" />
      </material>
    </visual>
    <collision>
      <origin
        xyz="0 0 0"
        rpy="0 0 0" />
      <geometry>
        <mesh
          filename="file://$(find robot_bringup)/meshes/fix_femur1_3.STL" />
      </geometry>
    </collision>
  </link>
  <joint
    name="femur1_3"
    type="fixed">
    <origin
      xyz="0 0 0"
      rpy="0 0 0" />
    <parent
      link="revolute_left_femur1_1" />
    <child
      link="fix_femur1_3" />
    <axis
      xyz="0 0 0" />
  </joint>
  <link
    name="fix_femur1_4">
    <inertial>
      <origin
        xyz="-2.0817E-17 -9.7145E-17 0.0494"
        rpy="0 0 0" />
      <mass
        value="0.0003" />
      <inertia
        ixx="7.2605E-09"
        ixy="-4.1175E-24"
        ixz="-5.5707E-25"
        iyy="7.2605E-09"
        iyz="-7.9711E-25"
        izz="1.3645E-08" />
    </inertial>
    <visual>
      <origin
        xyz="0 0 0"
        rpy="0 0 0" />
      <geometry>
        <mesh
          filename="file://$(find robot_bringup)/meshes/fix_femur1_4.STL" />
      </geometry>
      <material
        name="">
        <color
          rgba="0.79216 0.81961 0.93333 1" />
      </material>
    </visual>
    <collision>
      <origin
        xyz="0 0 0"
        rpy="0 0 0" />
      <geometry>
        <mesh
          filename="file://$(find robot_bringup)/meshes/fix_femur1_4.STL" />
      </geometry>
    </collision>
  </link>
  <joint
    name="femur1_4"
    type="fixed">
    <origin
      xyz="0 0 0"
      rpy="0 0 0" />
    <parent
      link="revolute_left_femur1_1" />
    <child
      link="fix_femur1_4" />
    <axis
      xyz="0 0 0" />
  </joint>
  <link
    name="fix_lefthip1motorbody">
    <inertial>
      <origin
        xyz="1.0408E-17 0.0093922 0.030086"
        rpy="0 0 0" />
      <mass
        value="0.008" />
      <inertia
        ixx="1.446E-06"
        ixy="-4.6045E-22"
        ixz="5.3961E-23"
        iyy="2.2752E-06"
        iyz="3.6652E-07"
        izz="2.2684E-06" />
    </inertial>
    <visual>
      <origin
        xyz="0 0 0"
        rpy="0 0 0" />
      <geometry>
        <mesh
          filename="file://$(find robot_bringup)/meshes/fix_lefthip1motorbody.STL" />
      </geometry>
      <material
        name="">
        <color
          rgba="0.79216 0.81961 0.93333 1" />
      </material>
    </visual>
    <collision>
      <origin
        xyz="0 0 0"
        rpy="0 0 0" />
      <geometry>
        <mesh
          filename="file://$(find robot_bringup)/meshes/fix_lefthip1motorbody.STL" />
      </geometry>
    </collision>
  </link>
  <joint
    name="lefthip1motorbody"
    type="fixed">
    <origin
      xyz="-0.0234 -0.09425 -0.024125"
      rpy="0 1.5707963267949 0" />
    <parent
      link="fix_leftlegtobaselink" />
    <child
      link="fix_lefthip1motorbody" />
    <axis
      xyz="0 0 0" />
  </joint>
  <link
    name="fix_rightlegtobaselink">
    <inertial>
      <origin
        xyz="-3.1196E-09 0.059316 0.0042205"
        rpy="0 0 0" />
      <mass
        value="0.028" />
      <inertia
        ixx="8.1588E-06"
        ixy="-1.3085E-13"
        ixz="4.33E-11"
        iyy="7.7241E-06"
        iyz="9.9424E-07"
        izz="8.6259E-06" />
    </inertial>
    <visual>
      <origin
        xyz="0 0 0"
        rpy="0 0 0" />
      <geometry>
        <mesh
          filename="file://$(find robot_bringup)/meshes/fix_rightlegtobaselink.STL" />
      </geometry>
      <material
        name="">
        <color
          rgba="0.79216 0.81961 0.93333 1" />
      </material>
    </visual>
    <collision>
      <origin
        xyz="0 0 0"
        rpy="0 0 0" />
      <geometry>
        <mesh
          filename="file://$(find robot_bringup)/meshes/fix_rightlegtobaselink.STL" />
      </geometry>
    </collision>
  </link>
  <joint
    name="rightlegtobaselink"
    type="fixed">
    <origin
      xyz="0 0 0"
      rpy="0 0 0" />
    <parent
      link="base_link" />
    <child
      link="fix_rightlegtobaselink" />
    <axis
      xyz="0 0 0" />
  </joint>
  <link
    name="fix_righthip1towaist">
    <inertial>
      <origin
        xyz="-0.00081105 0.082311 -0.024125"
        rpy="0 0 0" />
      <mass
        value="0.08" />
      <inertia
        ixx="1.0361E-05"
        ixy="2.2331E-07"
        ixz="2.3379E-17"
        iyy="6.7254E-06"
        iyz="-2.8598E-14"
        izz="1.1542E-05" />
    </inertial>
    <visual>
      <origin
        xyz="0 0 0"
        rpy="0 0 0" />
      <geometry>
        <mesh
          filename="file://$(find robot_bringup)/meshes/fix_righthip1towaist.STL" />
      </geometry>
      <material
        name="">
        <color
          rgba="0.79216 0.81961 0.93333 1" />
      </material>
    </visual>
    <collision>
      <origin
        xyz="0 0 0"
        rpy="0 0 0" />
      <geometry>
        <mesh
          filename="file://$(find robot_bringup)/meshes/fix_righthip1towaist.STL" />
      </geometry>
    </collision>
  </link>
  <joint
    name="righthip1towaist"
    type="fixed">
    <origin
      xyz="0 0 0"
      rpy="0 0 0" />
    <parent
      link="fix_rightlegtobaselink" />
    <child
      link="fix_righthip1towaist" />
    <axis
      xyz="0 0 0" />
  </joint>
  <link
    name="revolute_rightfemer1_1">
    <inertial>
      <origin
        xyz="-1.3878E-17 -0.019235 0.026145"
        rpy="0 0 0" />
      <mass
        value="0.016" />
      <inertia
        ixx="5.4156E-06"
        ixy="-6.7112E-24"
        ixz="4.1894E-23"
        iyy="4.4847E-06"
        iyz="-2.5399E-07"
        izz="1.6499E-06" />
    </inertial>
    <visual>
      <origin
        xyz="0 0 0"
        rpy="0 0 0" />
      <geometry>
        <mesh
          filename="file://$(find robot_bringup)/meshes/revolute_rightfemer1_1.STL" />
      </geometry>
      <material
        name="">
        <color
          rgba="1 1 1 1" />
      </material>
    </visual>
    <collision>
      <origin
        xyz="0 0 0"
        rpy="0 0 0" />
      <geometry>
        <mesh
          filename="file://$(find robot_bringup)/meshes/revolute_rightfemer1_1.STL" />
      </geometry>
    </collision>
  </link>
  <joint
    name="right_hip1"
    type="revolute">
    <origin
      xyz="-0.0234 0.09425 -0.024125"
      rpy="1.5707963267949 0 1.5707963267949" />
    <parent
      link="fix_righthip1towaist" />
    <child
      link="revolute_rightfemer1_1" />
    <axis
      xyz="0 0 -1" />
    <limit
      lower="-1.732"
      upper="1.732"
      effort="3.7"
      velocity="10" />
  </joint>
  <link
    name="fix_right_femer1_2">
    <inertial>
      <origin
        xyz="0.00081105 -0.048875 0.021339"
        rpy="0 0 0" />
      <mass
        value="0.08" />
      <inertia
        ixx="1.0361E-05"
        ixy="2.3366E-17"
        ixz="2.2331E-07"
        iyy="1.1542E-05"
        iyz="-2.8598E-14"
        izz="6.7254E-06" />
    </inertial>
    <visual>
      <origin
        xyz="0 0 0"
        rpy="0 0 0" />
      <geometry>
        <mesh
          filename="file://$(find robot_bringup)/meshes/fix_right_femer1_2.STL" />
      </geometry>
      <material
        name="">
        <color
          rgba="0.79216 0.81961 0.93333 1" />
      </material>
    </visual>
    <collision>
      <origin
        xyz="0 0 0"
        rpy="0 0 0" />
      <geometry>
        <mesh
          filename="file://$(find robot_bringup)/meshes/fix_right_femer1_2.STL" />
      </geometry>
    </collision>
  </link>
  <joint
    name="rightfemer1_2"
    type="fixed">
    <origin
      xyz="0 0 0"
      rpy="0 0 0" />
    <parent
      link="revolute_rightfemer1_1" />
    <child
      link="fix_right_femer1_2" />
    <axis
      xyz="0 0 0" />
  </joint>
  <link
    name="revolute_right_femur2_1">
    <inertial>
      <origin
        xyz="-1.5434E-11 -0.024976 -0.025952"
        rpy="0 0 0" />
      <mass
        value="0.016" />
      <inertia
        ixx="7.0717E-06"
        ixy="-1.5333E-15"
        ixz="2.8537E-12"
        iyy="4.694E-06"
        iyz="2.9746E-07"
        izz="3.2637E-06" />
    </inertial>
    <visual>
      <origin
        xyz="0 0 0"
        rpy="0 0 0" />
      <geometry>
        <mesh
          filename="file://$(find robot_bringup)/meshes/revolute_right_femur2_1.STL" />
      </geometry>
      <material
        name="">
        <color
          rgba="1 1 1 1" />
      </material>
    </visual>
    <collision>
      <origin
        xyz="0 0 0"
        rpy="0 0 0" />
      <geometry>
        <mesh
          filename="file://$(find robot_bringup)/meshes/revolute_right_femur2_1.STL" />
      </geometry>
    </collision>
  </link>
  <joint
    name="right_hip2"
    type="revolute">
    <origin
      xyz="0.0233999999999999 -0.048875 0.00940000000000001"
      rpy="0 1.5707963267949 0" />
    <parent
      link="fix_right_femer1_2" />
    <child
      link="revolute_right_femur2_1" />
    <axis
      xyz="0 0 -1" />
    <limit
      lower="-1.732"
      upper="1.732"
      effort="3.7"
      velocity="10" />
  </joint>
  <link
    name="fix_right_femur2_2">
    <inertial>
      <origin
        xyz="1.5435E-11 -0.13702 -0.025952"
        rpy="0 0 0" />
      <mass
        value="0.016" />
      <inertia
        ixx="7.0717E-06"
        ixy="-1.5333E-15"
        ixz="-2.8537E-12"
        iyy="4.694E-06"
        iyz="-2.9746E-07"
        izz="3.2637E-06" />
    </inertial>
    <visual>
      <origin
        xyz="0 0 0"
        rpy="0 0 0" />
      <geometry>
        <mesh
          filename="file://$(find robot_bringup)/meshes/fix_right_femur2_2.STL" />
      </geometry>
      <material
        name="">
        <color
          rgba="1 1 1 1" />
      </material>
    </visual>
    <collision>
      <origin
        xyz="0 0 0"
        rpy="0 0 0" />
      <geometry>
        <mesh
          filename="file://$(find robot_bringup)/meshes/fix_right_femur2_2.STL" />
      </geometry>
    </collision>
  </link>
  <joint
    name="right_femur2_2"
    type="fixed">
    <origin
      xyz="0 0 0"
      rpy="0 0 0" />
    <parent
      link="revolute_right_femur2_1" />
    <child
      link="fix_right_femur2_2" />
    <axis
      xyz="0 0 0" />
  </joint>
  <link
    name="revolute_right_knee">
    <inertial>
      <origin
        xyz="-6.9722E-13 -0.011939 -0.022589"
        rpy="0 0 0" />
      <mass
        value="0.08" />
      <inertia
        ixx="1.1542E-05"
        ixy="-2.8598E-14"
        ixz="-2.3381E-17"
        iyy="6.7254E-06"
        iyz="-2.2331E-07"
        izz="1.0361E-05" />
    </inertial>
    <visual>
      <origin
        xyz="0 0 0"
        rpy="0 0 0" />
      <geometry>
        <mesh
          filename="file://$(find robot_bringup)/meshes/revolute_right_knee.STL" />
      </geometry>
      <material
        name="">
        <color
          rgba="0.79216 0.81961 0.93333 1" />
      </material>
    </visual>
    <collision>
      <origin
        xyz="0 0 0"
        rpy="0 0 0" />
      <geometry>
        <mesh
          filename="file://$(find robot_bringup)/meshes/revolute_right_knee.STL" />
      </geometry>
    </collision>
  </link>
  <joint
    name="right_knee"
    type="revolute">
    <origin
      xyz="0 -0.162000000000005 0"
      rpy="0 0 0" />
    <parent
      link="fix_right_femur2_2" />
    <child
      link="revolute_right_knee" />
    <axis
      xyz="0 0 -1" />
    <limit
      lower="-2"
      upper="2"
      effort="5"
      velocity="10" />
  </joint>
  <link
    name="fix_righttibia_1">
    <inertial>
      <origin
        xyz="8.9841E-06 -0.16908 -0.022299"
        rpy="0 0 0" />
      <mass
        value="0.04" />
      <inertia
        ixx="1.096E-05"
        ixy="4.4082E-09"
        ixz="-5.2455E-09"
        iyy="6.3088E-06"
        iyz="2.5553E-07"
        izz="9.8712E-06" />
    </inertial>
    <visual>
      <origin
        xyz="0 0 0"
        rpy="0 0 0" />
      <geometry>
        <mesh
          filename="file://$(find robot_bringup)/meshes/fix_righttibia_1.STL" />
      </geometry>
      <material
        name="">
        <color
          rgba="0.79216 0.81961 0.93333 1" />
      </material>
    </visual>
    <collision>
      <origin
        xyz="0 0 0"
        rpy="0 0 0" />
      <geometry>
        <mesh
          filename="file://$(find robot_bringup)/meshes/fix_righttibia_1.STL" />
      </geometry>
    </collision>
  </link>
  <joint
    name="righttibia_1"
    type="fixed">
    <origin
      xyz="0 0 0"
      rpy="0 0 0" />
    <parent
      link="revolute_right_knee" />
    <child
      link="fix_righttibia_1" />
    <axis
      xyz="0 0 0" />
  </joint>
  <link
    name="revolute_rightfoot">
    <inertial>
      <origin
        xyz="-1.6064E-07 -0.028804 -0.033846"
        rpy="0 0 0" />
      <mass
        value="0.05" />
      <inertia
        ixx="3.7481E-05"
        ixy="-5.5007E-11"
        ixz="-6.021E-11"
        iyy="0.00015493"
        iyz="-3.0716E-06"
        izz="0.00012863" />
    </inertial>
    <visual>
      <origin
        xyz="0 0 0"
        rpy="0 0 0" />
      <geometry>
        <mesh
          filename="file://$(find robot_bringup)/meshes/revolute_rightfoot.STL" />
      </geometry>
      <material
        name="">
        <color
          rgba="0.79216 0.81961 0.93333 1" />
      </material>
    </visual>
    <collision>
      <origin
        xyz="0 0 0"
        rpy="0 0 0" />
      <geometry>
        <mesh
          filename="file://$(find robot_bringup)/meshes/revolute_rightfoot.STL" />
      </geometry>
    </collision>
  </link>
  <joint
    name="right_ankle"
    type="revolute">
    <origin
      xyz="0 -0.181000000000001 -0.00250000000000579"
      rpy="0 0 0" />
    <parent
      link="fix_righttibia_1" />
    <child
      link="revolute_rightfoot" />
    <axis
      xyz="0 0 -1" />
    <limit
      lower="-1.732"
      upper="1.732"
      effort="1.5"
      velocity="10" />
  </joint>
  <link
    name="fix_righttibia_2">
    <inertial>
      <origin
        xyz="-3.4573E-15 -0.13991 -0.0234"
        rpy="0 0 0" />
      <mass
        value="0.01" />
      <inertia
        ixx="8.4456E-07"
        ixy="7.5676E-20"
        ixz="1.598E-13"
        iyy="1.1166E-06"
        iyz="-9.714E-20"
        izz="1.4884E-06" />
    </inertial>
    <visual>
      <origin
        xyz="0 0 0"
        rpy="0 0 0" />
      <geometry>
        <mesh
          filename="file://$(find robot_bringup)/meshes/fix_righttibia_2.STL" />
      </geometry>
      <material
        name="">
        <color
          rgba="1 1 1 1" />
      </material>
    </visual>
    <collision>
      <origin
        xyz="0 0 0"
        rpy="0 0 0" />
      <geometry>
        <mesh
          filename="file://$(find robot_bringup)/meshes/fix_righttibia_2.STL" />
      </geometry>
    </collision>
  </link>
  <joint
    name="righttibia_2"
    type="fixed">
    <origin
      xyz="0 0 0"
      rpy="0 0 0" />
    <parent
      link="revolute_right_knee" />
    <child
      link="fix_righttibia_2" />
    <axis
      xyz="0 0 0" />
  </joint>
  <link
    name="fix_righttibia_3">
    <inertial>
      <origin
        xyz="0.00077912 -0.1234 -0.026003"
        rpy="0 0 0" />
      <mass
        value="0.0008" />
      <inertia
        ixx="8.7805E-08"
        ixy="7.4808E-23"
        ixz="8.4902E-09"
        iyy="1.4099E-07"
        iyz="3.841E-23"
        izz="6.0985E-08" />
    </inertial>
    <visual>
      <origin
        xyz="0 0 0"
        rpy="0 0 0" />
      <geometry>
        <mesh
          filename="file://$(find robot_bringup)/meshes/fix_righttibia_3.STL" />
      </geometry>
      <material
        name="">
        <color
          rgba="0.79216 0.81961 0.93333 1" />
      </material>
    </visual>
    <collision>
      <origin
        xyz="0 0 0"
        rpy="0 0 0" />
      <geometry>
        <mesh
          filename="file://$(find robot_bringup)/meshes/fix_righttibia_3.STL" />
      </geometry>
    </collision>
  </link>
  <joint
    name="righttibia_3"
    type="fixed">
    <origin
      xyz="0 0 0"
      rpy="0 0 0" />
    <parent
      link="revolute_right_knee" />
    <child
      link="fix_righttibia_3" />
    <axis
      xyz="0 0 0" />
  </joint>
  <link
    name="fix_righttibia_4">
    <inertial>
      <origin
        xyz="5.0307E-17 -0.0905 -0.0234"
        rpy="0 0 0" />
      <mass
        value="0.007" />
      <inertia
        ixx="2.3852E-06"
        ixy="-6.0832E-22"
        ixz="7.7548E-24"
        iyy="5.7962E-08"
        iyz="-3.4962E-21"
        izz="2.3852E-06" />
    </inertial>
    <visual>
      <origin
        xyz="0 0 0"
        rpy="0 0 0" />
      <geometry>
        <mesh
          filename="file://$(find robot_bringup)/meshes/fix_righttibia_4.STL" />
      </geometry>
      <material
        name="">
        <color
          rgba="0.79216 0.81961 0.93333 1" />
      </material>
    </visual>
    <collision>
      <origin
        xyz="0 0 0"
        rpy="0 0 0" />
      <geometry>
        <mesh
          filename="file://$(find robot_bringup)/meshes/fix_righttibia_4.STL" />
      </geometry>
    </collision>
  </link>
  <joint
    name="righttibia_4"
    type="fixed">
    <origin
      xyz="0 0 0"
      rpy="0 0 0" />
    <parent
      link="revolute_right_knee" />
    <child
      link="fix_righttibia_4" />
    <axis
      xyz="0 0 0" />
  </joint>
  <link
    name="fix_righttibia_5">
    <inertial>
      <origin
        xyz="-3.8893E-15 -0.04109 -0.0234"
        rpy="0 0 0" />
      <mass
        value="0.01" />
      <inertia
        ixx="8.4456E-07"
        ixy="-7.5064E-20"
        ixz="-1.598E-13"
        iyy="1.1166E-06"
        iyz="-9.6815E-20"
        izz="1.4884E-06" />
    </inertial>
    <visual>
      <origin
        xyz="0 0 0"
        rpy="0 0 0" />
      <geometry>
        <mesh
          filename="file://$(find robot_bringup)/meshes/fix_righttibia_5.STL" />
      </geometry>
      <material
        name="">
        <color
          rgba="1 1 1 1" />
      </material>
    </visual>
    <collision>
      <origin
        xyz="0 0 0"
        rpy="0 0 0" />
      <geometry>
        <mesh
          filename="file://$(find robot_bringup)/meshes/fix_righttibia_5.STL" />
      </geometry>
    </collision>
  </link>
  <joint
    name="righttibia_5"
    type="fixed">
    <origin
      xyz="0 0 0"
      rpy="0 0 0" />
    <parent
      link="revolute_right_knee" />
    <child
      link="fix_righttibia_5" />
    <axis
      xyz="0 0 0" />
  </joint>
  <link
    name="fix_righttibia_6">
    <inertial>
      <origin
        xyz="-7.8063E-17 -0.00179 -0.035364"
        rpy="0 0 0" />
      <mass
        value="0.004" />
      <inertia
        ixx="4.093E-07"
        ixy="4.9597E-23"
        ixz="-1.5841E-22"
        iyy="1.0855E-06"
        iyz="-1.343E-09"
        izz="7.5439E-07" />
    </inertial>
    <visual>
      <origin
        xyz="0 0 0"
        rpy="0 0 0" />
      <geometry>
        <mesh
          filename="file://$(find robot_bringup)/meshes/fix_righttibia_6.STL" />
      </geometry>
      <material
        name="">
        <color
          rgba="0.79216 0.81961 0.93333 1" />
      </material>
    </visual>
    <collision>
      <origin
        xyz="0 0 0"
        rpy="0 0 0" />
      <geometry>
        <mesh
          filename="file://$(find robot_bringup)/meshes/fix_righttibia_6.STL" />
      </geometry>
    </collision>
  </link>
  <joint
    name="righttibia_6"
    type="fixed">
    <origin
      xyz="0 0 0"
      rpy="0 0 0" />
    <parent
      link="revolute_right_knee" />
    <child
      link="fix_righttibia_6" />
    <axis
      xyz="0 0 0" />
  </joint>
  <link
    name="fix_right_femur2_3">
    <inertial>
      <origin
        xyz="9.1073E-16 -0.081 -0.0254"
        rpy="0 0 0" />
      <mass
        value="0.007" />
      <inertia
        ixx="2.3852E-06"
        ixy="-9.7387E-22"
        ixz="-1.4648E-24"
        iyy="5.7962E-08"
        iyz="7.6195E-22"
        izz="2.3852E-06" />
    </inertial>
    <visual>
      <origin
        xyz="0 0 0"
        rpy="0 0 0" />
      <geometry>
        <mesh
          filename="file://$(find robot_bringup)/meshes/fix_right_femur2_3.STL" />
      </geometry>
      <material
        name="">
        <color
          rgba="0.79216 0.81961 0.93333 1" />
      </material>
    </visual>
    <collision>
      <origin
        xyz="0 0 0"
        rpy="0 0 0" />
      <geometry>
        <mesh
          filename="file://$(find robot_bringup)/meshes/fix_right_femur2_3.STL" />
      </geometry>
    </collision>
  </link>
  <joint
    name="right_femur2_3"
    type="fixed">
    <origin
      xyz="0 0 0"
      rpy="0 0 0" />
    <parent
      link="revolute_right_femur2_1" />
    <child
      link="fix_right_femur2_3" />
    <axis
      xyz="0 0 0" />
  </joint>
  <link
    name="fix_rightfemer1_3">
    <inertial>
      <origin
        xyz="-0.0066861 -0.048875 0.018792"
        rpy="0 0 0" />
      <mass
        value="0.008" />
      <inertia
        ixx="2.2684E-06"
        ixy="-7.6294E-22"
        ixz="-3.6652E-07"
        iyy="1.446E-06"
        iyz="-5.8617E-22"
        izz="2.2752E-06" />
    </inertial>
    <visual>
      <origin
        xyz="0 0 0"
        rpy="0 0 0" />
      <geometry>
        <mesh
          filename="file://$(find robot_bringup)/meshes/fix_rightfemer1_3.STL" />
      </geometry>
      <material
        name="">
        <color
          rgba="0.79216 0.81961 0.93333 1" />
      </material>
    </visual>
    <collision>
      <origin
        xyz="0 0 0"
        rpy="0 0 0" />
      <geometry>
        <mesh
          filename="file://$(find robot_bringup)/meshes/fix_rightfemer1_3.STL" />
      </geometry>
    </collision>
  </link>
  <joint
    name="rightfemer1_3"
    type="fixed">
    <origin
      xyz="0 0 0"
      rpy="0 0 0" />
    <parent
      link="revolute_rightfemer1_1" />
    <child
      link="fix_rightfemer1_3" />
    <axis
      xyz="0 0 0" />
  </joint>
  <link
    name="fix_rightfemer1_4">
    <inertial>
      <origin
        xyz="-4.1633E-17 4.1633E-17 0.0494"
        rpy="0 0 0" />
      <mass
        value="0.0003" />
      <inertia
        ixx="7.2605E-09"
        ixy="1.6111E-24"
        ixz="-2.095E-25"
        iyy="7.2605E-09"
        iyz="-5.894E-25"
        izz="1.3645E-08" />
    </inertial>
    <visual>
      <origin
        xyz="0 0 0"
        rpy="0 0 0" />
      <geometry>
        <mesh
          filename="file://$(find robot_bringup)/meshes/fix_rightfemer1_4.STL" />
      </geometry>
      <material
        name="">
        <color
          rgba="0.79216 0.81961 0.93333 1" />
      </material>
    </visual>
    <collision>
      <origin
        xyz="0 0 0"
        rpy="0 0 0" />
      <geometry>
        <mesh
          filename="file://$(find robot_bringup)/meshes/fix_rightfemer1_4.STL" />
      </geometry>
    </collision>
  </link>
  <joint
    name="rightfemer1_4"
    type="fixed">
    <origin
      xyz="0 0 0"
      rpy="0 0 0" />
    <parent
      link="revolute_rightfemer1_1" />
    <child
      link="fix_rightfemer1_4" />
    <axis
      xyz="0 0 0" />
  </joint>
  <link
    name="fix_right_hip1motorbody">
    <inertial>
      <origin
        xyz="0.0066861 0.084858 -0.024125"
        rpy="0 0 0" />
      <mass
        value="0.008" />
      <inertia
        ixx="2.2684E-06"
        ixy="-3.6652E-07"
        ixz="4.9767E-23"
        iyy="2.2752E-06"
        iyz="-4.3615E-22"
        izz="1.446E-06" />
    </inertial>
    <visual>
      <origin
        xyz="0 0 0"
        rpy="0 0 0" />
      <geometry>
        <mesh
          filename="file://$(find robot_bringup)/meshes/fix_right_hip1motorbody.STL" />
      </geometry>
      <material
        name="">
        <color
          rgba="0.79216 0.81961 0.93333 1" />
      </material>
    </visual>
    <collision>
      <origin
        xyz="0 0 0"
        rpy="0 0 0" />
      <geometry>
        <mesh
          filename="file://$(find robot_bringup)/meshes/fix_right_hip1motorbody.STL" />
      </geometry>
    </collision>
  </link>
  <joint
    name="right_hip1motorbody"
    type="fixed">
    <origin
      xyz="0 0 0"
      rpy="0 0 0" />
    <parent
      link="fix_rightlegtobaselink" />
    <child
      link="fix_right_hip1motorbody" />
    <axis
      xyz="0 0 0" />
  </joint>
  <link
    name="fix_torsotobaselink1">
    <inertial>
      <origin
        xyz="-0.0012031 1.5888E-18 0.024015"
        rpy="0 0 0" />
      <mass
        value="0.02" />
      <inertia
        ixx="5.3699E-06"
        ixy="-2.5375E-21"
        ixz="4.9395E-07"
        iyy="1.0212E-05"
        iyz="6.478E-21"
        izz="1.098E-05" />
    </inertial>
    <visual>
      <origin
        xyz="0 0 0"
        rpy="0 0 0" />
      <geometry>
        <mesh
          filename="file://$(find robot_bringup)/meshes/fix_torsotobaselink1.STL" />
      </geometry>
      <material
        name="">
        <color
          rgba="0.79216 0.81961 0.93333 1" />
      </material>
    </visual>
    <collision>
      <origin
        xyz="0 0 0"
        rpy="0 0 0" />
      <geometry>
        <mesh
          filename="file://$(find robot_bringup)/meshes/fix_torsotobaselink1.STL" />
      </geometry>
    </collision>
  </link>
  <joint
    name="torsotobaselink1"
    type="fixed">
    <origin
      xyz="0 0 0"
      rpy="0 0 0" />
    <parent
      link="base_link" />
    <child
      link="fix_torsotobaselink1" />
    <axis
      xyz="0 0 0" />
  </joint>
  <link
    name="servo1">
    <inertial>
      <origin
        xyz="-7.7571E-11 0.015029 -0.029118"
        rpy="0 0 0" />
      <mass
        value="0.165" />
      <inertia
        ixx="3.834E-05"
        ixy="4.775E-14"
        ixz="-8.2973E-14"
        iyy="2.1548E-05"
        iyz="1.6188E-07"
        izz="3.1728E-05" />
    </inertial>
    <visual>
      <origin
        xyz="0 0 0"
        rpy="0 0 0" />
      <geometry>
        <mesh
          filename="file://$(find robot_bringup)/meshes/servo1.STL" />
      </geometry>
      <material
        name="">
        <color
          rgba="0.79216 0.81961 0.93333 1" />
      </material>
    </visual>
    <collision>
      <origin
        xyz="0 0 0"
        rpy="0 0 0" />
      <geometry>
        <mesh
          filename="file://$(find robot_bringup)/meshes/servo1.STL" />
      </geometry>
    </collision>
  </link>
  <joint
    name="torso"
    type="revolute">
    <origin
      xyz="0.0298000000000001 0 0.0422500000000002"
      rpy="1.57079632679489 0 1.5707963267949" />
    <parent
      link="fix_torsotobaselink1" />
    <child
      link="servo1" />
    <axis
      xyz="0 0 1" />
    <limit
      lower="-1.732"
      upper="1.732"
      effort="13"
      velocity="10" />
  </joint>
  <link
    name="fix_torsolink1">
    <inertial>
      <origin
        xyz="-0.00015 0.049553 -0.0298"
        rpy="0 0 0" />
      <mass
        value="0.01" />
      <inertia
        ixx="1.0537E-06"
        ixy="1.3742E-22"
        ixz="8.0242E-15"
        iyy="1.857E-06"
        iyz="-1.3041E-22"
        izz="2.1198E-06" />
    </inertial>
    <visual>
      <origin
        xyz="0 0 0"
        rpy="0 0 0" />
      <geometry>
        <mesh
          filename="file://$(find robot_bringup)/meshes/fix_torsolink1.STL" />
      </geometry>
      <material
        name="">
        <color
          rgba="1 1 1 1" />
      </material>
    </visual>
    <collision>
      <origin
        xyz="0 0 0"
        rpy="0 0 0" />
      <geometry>
        <mesh
          filename="file://$(find robot_bringup)/meshes/fix_torsolink1.STL" />
      </geometry>
    </collision>
  </link>
  <joint
    name="torsolink1"
    type="fixed">
    <origin
      xyz="0 0 0"
      rpy="0 0 0" />
    <parent
      link="servo1" />
    <child
      link="fix_torsolink1" />
    <axis
      xyz="0 0 0" />
  </joint>
  <link
    name="fix_torsolink2">
    <inertial>
      <origin
        xyz="-0.00015 0.20875 -0.0298"
        rpy="0 0 0" />
      <mass
        value="0.015" />
      <inertia
        ixx="5.848E-05"
        ixy="-5.1101E-21"
        ixz="-9.0783E-24"
        iyy="1.4923E-07"
        iyz="-1.4156E-19"
        izz="5.848E-05" />
    </inertial>
    <visual>
      <origin
        xyz="0 0 0"
        rpy="0 0 0" />
      <geometry>
        <mesh
          filename="file://$(find robot_bringup)/meshes/fix_torsolink2.STL" />
      </geometry>
      <material
        name="">
        <color
          rgba="0.79216 0.81961 0.93333 1" />
      </material>
    </visual>
    <collision>
      <origin
        xyz="0 0 0"
        rpy="0 0 0" />
      <geometry>
        <mesh
          filename="file://$(find robot_bringup)/meshes/fix_torsolink2.STL" />
      </geometry>
    </collision>
  </link>
  <joint
    name="torsolink2"
    type="fixed">
    <origin
      xyz="0 0 0"
      rpy="0 0 0" />
    <parent
      link="servo1" />
    <child
      link="fix_torsolink2" />
    <axis
      xyz="0 0 0" />
  </joint>
  <link
    name="fix_torsolink3">
    <inertial>
      <origin
        xyz="-0.00015 0.36452 -0.0298"
        rpy="0 0 0" />
      <mass
        value="0.006" />
      <inertia
        ixx="6.0919E-07"
        ixy="1.386E-22"
        ixz="1.2785E-17"
        iyy="5.457E-07"
        iyz="-2.4494E-22"
        izz="7.0719E-07" />
    </inertial>
    <visual>
      <origin
        xyz="0 0 0"
        rpy="0 0 0" />
      <geometry>
        <mesh
          filename="file://$(find robot_bringup)/meshes/fix_torsolink3.STL" />
      </geometry>
      <material
        name="">
        <color
          rgba="1 1 1 1" />
      </material>
    </visual>
    <collision>
      <origin
        xyz="0 0 0"
        rpy="0 0 0" />
      <geometry>
        <mesh
          filename="file://$(find robot_bringup)/meshes/fix_torsolink3.STL" />
      </geometry>
    </collision>
  </link>
  <joint
    name="torsolink3"
    type="fixed">
    <origin
      xyz="0 0 0"
      rpy="0 0 0" />
    <parent
      link="servo1" />
    <child
      link="fix_torsolink3" />
    <axis
      xyz="0 0 0" />
  </joint>
  <link
    name="fix_torsoweight">
    <inertial>
      <origin
        xyz="-0.00015 0.37425 -0.0298"
        rpy="0 0 0" />
      <mass
        value="0.22" />
      <inertia
        ixx="2.2936E-05"
        ixy="-1.0029E-21"
        ixz="3.3123E-22"
        iyy="4.5838E-05"
        iyz="5.2146E-20"
        izz="2.2933E-05" />
    </inertial>
    <visual>
      <origin
        xyz="0 0 0"
        rpy="0 0 0" />
      <geometry>
        <mesh
          filename="file://$(find robot_bringup)/meshes/fix_torsoweight.STL" />
      </geometry>
      <material
        name="">
        <color
          rgba="0.79216 0.81961 0.93333 1" />
      </material>
    </visual>
    <collision>
      <origin
        xyz="0 0 0"
        rpy="0 0 0" />
      <geometry>
        <mesh
          filename="file://$(find robot_bringup)/meshes/fix_torsoweight.STL" />
      </geometry>
    </collision>
  </link>
  <joint
    name="torsoweight"
    type="fixed">
    <origin
      xyz="0 0 0"
      rpy="0 0 0" />
    <parent
      link="servo1" />
    <child
      link="fix_torsoweight" />
    <axis
      xyz="0 0 0" />
  </joint>
  <link
    name="fix_torsotobaselink2">
    <inertial>
      <origin
        xyz="-2.3201E-18 7.7378E-18 0.01875"
        rpy="0 0 0" />
      <mass
        value="0.008" />
      <inertia
        ixx="2.331E-06"
        ixy="-1.593E-21"
        ixz="-5.911E-23"
        iyy="1.9323E-06"
        iyz="5.3201E-22"
        izz="4.2505E-06" />
    </inertial>
    <visual>
      <origin
        xyz="0 0 0"
        rpy="0 0 0" />
      <geometry>
        <mesh
          filename="file://$(find robot_bringup)/meshes/fix_torsotobaselink2.STL" />
      </geometry>
      <material
        name="">
        <color
          rgba="0.79216 0.81961 0.93333 1" />
      </material>
    </visual>
    <collision>
      <origin
        xyz="0 0 0"
        rpy="0 0 0" />
      <geometry>
        <mesh
          filename="file://$(find robot_bringup)/meshes/fix_torsotobaselink2.STL" />
      </geometry>
    </collision>
  </link>
  <joint
    name="torsotobaselink"
    type="fixed">
    <origin
      xyz="0 0 0"
      rpy="0 0 0" />
    <parent
      link="base_link" />
    <child
      link="fix_torsotobaselink2" />
    <axis
      xyz="0 0 0" />
  </joint>
  <link
    name="fix_cfpipe1tobaselink">
    <inertial>
      <origin
        xyz="0.01375 2.1582E-18 0.00925"
        rpy="0 0 0" />
      <mass
        value="0.007" />
      <inertia
        ixx="2.4432E-06"
        ixy="6.3549E-38"
        ixz="0"
        iyy="5.162E-08"
        iyz="5.5801E-22"
        izz="2.4432E-06" />
    </inertial>
    <visual>
      <origin
        xyz="0 0 0"
        rpy="0 0 0" />
      <geometry>
        <mesh
          filename="file://$(find robot_bringup)/meshes/fix_cfpipe1tobaselink.STL" />
      </geometry>
      <material
        name="">
        <color
          rgba="1 1 1 1" />
      </material>
    </visual>
    <collision>
      <origin
        xyz="0 0 0"
        rpy="0 0 0" />
      <geometry>
        <mesh
          filename="file://$(find robot_bringup)/meshes/fix_cfpipe1tobaselink.STL" />
      </geometry>
    </collision>
  </link>
  <joint
    name="cfpipe1tobaselink"
    type="fixed">
    <origin
      xyz="0 0 0"
      rpy="0 0 0" />
    <parent
      link="base_link" />
    <child
      link="fix_cfpipe1tobaselink" />
    <axis
      xyz="0 1 0" />
  </joint>
  <link
    name="fix_cfpipe2tobaselink">
    <inertial>
      <origin
        xyz="-0.01375 2.1582E-18 0.00925"
        rpy="0 0 0" />
      <mass
        value="0.007" />
      <inertia
        ixx="2.4432E-06"
        ixy="6.3549E-38"
        ixz="0"
        iyy="5.162E-08"
        iyz="5.5801E-22"
        izz="2.4432E-06" />
    </inertial>
    <visual>
      <origin
        xyz="0 0 0"
        rpy="0 0 0" />
      <geometry>
        <mesh
          filename="file://$(find robot_bringup)/meshes/fix_cfpipe2tobaselink.STL" />
      </geometry>
      <material
        name="">
        <color
          rgba="1 1 1 1" />
      </material>
    </visual>
    <collision>
      <origin
        xyz="0 0 0"
        rpy="0 0 0" />
      <geometry>
        <mesh
          filename="file://$(find robot_bringup)/meshes/fix_cfpipe2tobaselink.STL" />
      </geometry>
    </collision>
  </link>
  <joint
    name="cfpipe2tobaselink"
    type="fixed">
    <origin
      xyz="0 0 0"
      rpy="0 0 0" />
    <parent
      link="base_link" />
    <child
      link="fix_cfpipe2tobaselink" />
    <axis
      xyz="0 0 0" />
  </joint>

  <ros2_control name="leg" type="system">
    <hardware>
        <xacro:if value="$(arg USE_WITH_SIM)">
            <plugin>gz_ros2_control/GazeboSimSystem</plugin>
        </xacro:if>
        <xacro:unless value="$(arg USE_WITH_SIM)">
          <plugin>dynamixel_hardware/DynamixelHardware</plugin>
          <param name="usb_port">/dev/ttyUSB0</param>
          <param name="baud_rate">57600</param>
          <param name="control_mode">position</param>
        </xacro:unless>
    </hardware>
    <joint name="right_hip1">
        <param name="id">1</param>
        <command_interface name="position"/>
        <!-- <command_interface name="velocity"/> -->
        <state_interface name="position"/>
        <state_interface name="velocity"/>
    </joint>
    <joint name="right_hip2">
        <param name="id">2</param>
        <command_interface name="position"/>
        <!-- <command_interface name="velocity"/> -->
        <state_interface name="position"/>
        <state_interface name="velocity"/>
    </joint>
    <joint name="right_knee">
        <param name="id">3</param>
        <command_interface name="position"/>
        <!-- <command_interface name="velocity"/> -->
        <state_interface name="position"/>
        <state_interface name="velocity"/>
    </joint>
    <joint name="left_hip1">
        <param name="id">5</param>
        <command_interface name="position"/>
        <!-- <command_interface name="velocity"/> -->
        <state_interface name="position"/>
        <state_interface name="velocity"/>
    </joint>
    <joint name="left_hip2">
        <param name="id">6</param>
        <command_interface name="position"/>
        <!-- <command_interface name="velocity"/> -->
        <state_interface name="position"/>
        <state_interface name="velocity"/>
    </joint>
    <joint name="left_knee">
        <param name="id">7</param>
        <command_interface name="position"/>
        <!-- <command_interface name="velocity"/> -->
        <state_interface name="position"/>
        <state_interface name="velocity"/>
    </joint>
    <joint name="right_ankle">
        <param name="id">4</param>
        <command_interface name="position"/>
        <!-- <command_interface name="velocity"/> -->
        <state_interface name="position"/>
        <state_interface name="velocity"/>
    </joint>
    <joint name="left_ankle">
        <param name="id">8</param>
        <command_interface name="position"/>
        <!-- <command_interface name="velocity"/> -->
        <state_interface name="position"/>
        <state_interface name="velocity"/>
    </joint>
    <joint name="torso">
        <param name="id">9</param>
        <command_interface name="position"/>
        <!-- <command_interface name="velocity"/> -->
        <state_interface name="position"/>
        <state_interface name="velocity"/>
    </joint>
</ros2_control>


<xacro:if value="$(arg USE_WITH_SIM)">
      <gazebo>
          <plugin filename="gz_ros2_control-system" name="gz_ros2_control::GazeboSimROS2ControlPlugin">
              <parameters>$(find robot_bringup)/config/biped.yaml</parameters>
              <ros>
                  <namespace>/$(arg NAMESPACE)</namespace>
              </ros>
          </plugin>
      </gazebo>
  </xacro:if>

</robot>