<?xml version="1.0" encoding="utf-8"?>
<robot xmlns:xacro="http://www.ros.org/wiki/xacro"
  name="biped_v3">
    <!-- WORLD -->
  <link name="world"/>

  <!-- BASE LINK -->
  <joint name="base_joint" type="fixed">
    <parent link="world"/>
    <child link="base_link"/>
    <origin rpy="0 0 0" xyz="0.0 0.0 1.0"/>
  </joint>
  
  <link
    name="base_link">
    <inertial>
      <origin
        xyz="-2.5975E-19 1.2111E-17 0.0040839"
        rpy="0 0 0" />
      <mass
        value="0.03" />
      <inertia
        ixx="8.1069E-06"
        ixy="3.6344E-21"
        ixz="-1.5083E-21"
        iyy="8.5785E-06"
        iyz="1.6867E-21"
        izz="1.6342E-05" />
    </inertial>
    <visual>
      <origin
        xyz="0 0 0"
        rpy="0 0 0" />
      <geometry>
        <mesh
          filename="file://$(find robot_bringup)/meshes/base_link.STL" />
      </geometry>
      <material
        name="">
        <color
          rgba="0.5 0.5 0.5 1" />
      </material>
    </visual>
    <collision>
      <origin
        xyz="0 0 0"
        rpy="0 0 0" />
      <geometry>
        <mesh
          filename="file://$(find robot_bringup)/meshes/base_link.STL" />
      </geometry>
    </collision>
  </link>
  <link
    name="fix_leftlegtobaselink">
    <inertial>
      <origin
        xyz="3.1196E-09 -0.079316 0.0042205"
        rpy="0 0 0" />
      <mass
        value="0.028" />
      <inertia
        ixx="8.1588E-06"
        ixy="-1.3085E-13"
        ixz="-4.33E-11"
        iyy="7.7241E-06"
        iyz="-9.9424E-07"
        izz="8.6259E-06" />
    </inertial>
    <visual>
      <origin
        xyz="0 0 0"
        rpy="0 0 0" />
      <geometry>
        <mesh
          filename="file://$(find robot_bringup)/meshes/fix_leftlegtobaselink.STL" />
      </geometry>
      <material
        name="">
        <color
          rgba="0.5 0.5 0.5 1" />
      </material>
    </visual>
    <collision>
      <origin
        xyz="0 0 0"
        rpy="0 0 0" />
      <geometry>
        <mesh
          filename="file://$(find robot_bringup)/meshes/fix_leftlegtobaselink.STL" />
      </geometry>
    </collision>
  </link>
  <joint
    name="leftlegtobaselink"
    type="fixed">
    <origin
      xyz="0 0 0"
      rpy="0 0 0" />
    <parent
      link="base_link" />
    <child
      link="fix_leftlegtobaselink" />
    <axis
      xyz="0 0 0" />
  </joint>
  <link
    name="fix_lefthip1towaist">
    <inertial>
      <origin
        xyz="-0.00081105 -0.10231 -0.024125"
        rpy="0 0 0" />
      <mass
        value="0.08" />
      <inertia
        ixx="1.0361E-05"
        ixy="-2.2331E-07"
        ixz="-2.3377E-17"
        iyy="6.7254E-06"
        iyz="-2.8598E-14"
        izz="1.1542E-05" />
    </inertial>
    <visual>
      <origin
        xyz="0 0 0"
        rpy="0 0 0" />
      <geometry>
        <mesh
          filename="file://$(find robot_bringup)/meshes/fix_lefthip1towaist.STL" />
      </geometry>
      <material
        name="">
        <color
          rgba="0.25 0.25 0.25 1" />
      </material>
    </visual>
    <collision>
      <origin
        xyz="0 0 0"
        rpy="0 0 0" />
      <geometry>
        <mesh
          filename="file://$(find robot_bringup)/meshes/fix_lefthip1towaist.STL" />
      </geometry>
    </collision>
  </link>
  <joint
    name="lefthip1towaist"
    type="fixed">
    <origin
      xyz="0 0 0"
      rpy="0 0 0" />
    <parent
      link="fix_leftlegtobaselink" />
    <child
      link="fix_lefthip1towaist" />
    <axis
      xyz="0 0 0" />
  </joint>
  <link
    name="revolute_left_femur1_1">
    <inertial>
      <origin
        xyz="0.019235 -1.3878E-17 0.026145"
        rpy="0 0 0" />
      <mass
        value="0.016" />
      <inertia
        ixx="4.4847E-06"
        ixy="-3.3816E-22"
        ixz="2.5399E-07"
        iyy="5.4156E-06"
        iyz="6.6749E-22"
        izz="1.6499E-06" />
    </inertial>
    <visual>
      <origin
        xyz="0 0 0"
        rpy="0 0 0" />
      <geometry>
        <mesh
          filename="file://$(find robot_bringup)/meshes/revolute_left_femur1_1.STL" />
      </geometry>
      <material
        name="">
        <color
          rgba="0.4 0.4 0.4 1" />
      </material>
    </visual>
    <collision>
      <origin
        xyz="0 0 0"
        rpy="0 0 0" />
      <geometry>
        <mesh
          filename="file://$(find robot_bringup)/meshes/revolute_left_femur1_1.STL" />
      </geometry>
    </collision>
  </link>
  <joint
    name="left_hip1"
    type="revolute">
    <origin
      xyz="-0.0234 -0.11425 -0.024125"
      rpy="0 1.5708 0" />
    <parent
      link="fix_lefthip1towaist" />
    <child
      link="revolute_left_femur1_1" />
    <axis
      xyz="0 0 -1" />
    <limit
      lower="-1.732"
      upper="1.732"
      effort="3.7"
      velocity="10" />
  </joint>
  <link
    name="fix_leftfemur1_2">
    <inertial>
      <origin
        xyz="0.048875 -0.00081105 0.021339"
        rpy="0 0 0" />
      <mass
        value="0.08" />
      <inertia
        ixx="1.1542E-05"
        ixy="-2.3389E-17"
        ixz="-2.8598E-14"
        iyy="1.0361E-05"
        iyz="-2.2331E-07"
        izz="6.7254E-06" />
    </inertial>
    <visual>
      <origin
        xyz="0 0 0"
        rpy="0 0 0" />
      <geometry>
        <mesh
          filename="file://$(find robot_bringup)/meshes/fix_leftfemur1_2.STL" />
      </geometry>
      <material
        name="">
        <color
          rgba="0.25 0.25 0.25 1" />
      </material>
    </visual>
    <collision>
      <origin
        xyz="0 0 0"
        rpy="0 0 0" />
      <geometry>
        <mesh
          filename="file://$(find robot_bringup)/meshes/fix_leftfemur1_2.STL" />
      </geometry>
    </collision>
  </link>
  <joint
    name="leftfemur1_2"
    type="fixed">
    <origin
      xyz="0 0 0"
      rpy="0 0 0" />
    <parent
      link="revolute_left_femur1_1" />
    <child
      link="fix_leftfemur1_2" />
    <axis
      xyz="0 0 0" />
  </joint>
  <link
    name="revolute_left_femur2_1">
    <inertial>
      <origin
        xyz="-1.5434E-11 -0.024976 -0.025952"
        rpy="0 0 0" />
      <mass
        value="0.016" />
      <inertia
        ixx="7.0717E-06"
        ixy="-1.5333E-15"
        ixz="2.8537E-12"
        iyy="4.694E-06"
        iyz="2.9746E-07"
        izz="3.2637E-06" />
    </inertial>
    <visual>
      <origin
        xyz="0 0 0"
        rpy="0 0 0" />
      <geometry>
        <mesh
          filename="file://$(find robot_bringup)/meshes/revolute_left_femur2_1.STL" />
      </geometry>
      <material
        name="">
        <color
          rgba="0.4 0.4 0.4 1" />
      </material>
    </visual>
    <collision>
      <origin
        xyz="0 0 0"
        rpy="0 0 0" />
      <geometry>
        <mesh
          filename="file://$(find robot_bringup)/meshes/revolute_left_femur2_1.STL" />
      </geometry>
    </collision>
  </link>
  <joint
    name="left_hip2"
    type="revolute">
    <origin
      xyz="0.048875 -0.0234 0.0094"
      rpy="1.5708 -1.5708 0" />
    <parent
      link="fix_leftfemur1_2" />
    <child
      link="revolute_left_femur2_1" />
    <axis
      xyz="0 0 1" />
    <limit
      lower="-1.732"
      upper="1.732"
      effort="3.7"
      velocity="10" />
  </joint>
  <link
    name="fix_left_femur2_2">
    <inertial>
      <origin
        xyz="1.5434E-11 -0.18702 -0.025952"
        rpy="0 0 0" />
      <mass
        value="0.016" />
      <inertia
        ixx="7.0717E-06"
        ixy="-1.5333E-15"
        ixz="-2.8537E-12"
        iyy="4.694E-06"
        iyz="-2.9746E-07"
        izz="3.2637E-06" />
    </inertial>
    <visual>
      <origin
        xyz="0 0 0"
        rpy="0 0 0" />
      <geometry>
        <mesh
          filename="file://$(find robot_bringup)/meshes/fix_left_femur2_2.STL" />
      </geometry>
      <material
        name="">
        <color
          rgba="0.4 0.4 0.4 1" />
      </material>
    </visual>
    <collision>
      <origin
        xyz="0 0 0"
        rpy="0 0 0" />
      <geometry>
        <mesh
          filename="file://$(find robot_bringup)/meshes/fix_left_femur2_2.STL" />
      </geometry>
    </collision>
  </link>
  <joint
    name="left_femur2_2"
    type="fixed">
    <origin
      xyz="0 0 0"
      rpy="0 0 0" />
    <parent
      link="revolute_left_femur2_1" />
    <child
      link="fix_left_femur2_2" />
    <axis
      xyz="0 0 0" />
  </joint>
  <link
    name="revolute_left_knee">
    <inertial>
      <origin
        xyz="6.9716E-13 -0.011939 0.022589"
        rpy="0 0 0" />
      <mass
        value="0.08" />
      <inertia
        ixx="1.1542E-05"
        ixy="2.8598E-14"
        ixz="-2.3381E-17"
        iyy="6.7254E-06"
        iyz="2.2331E-07"
        izz="1.0361E-05" />
    </inertial>
    <visual>
      <origin
        xyz="0 0 0"
        rpy="0 0 0" />
      <geometry>
        <mesh
          filename="file://$(find robot_bringup)/meshes/revolute_left_knee.STL" />
      </geometry>
      <material
        name="">
        <color
          rgba="0.25 0.25 0.25 1" />
      </material>
    </visual>
    <collision>
      <origin
        xyz="0 0 0"
        rpy="0 0 0" />
      <geometry>
        <mesh
          filename="file://$(find robot_bringup)/meshes/revolute_left_knee.STL" />
      </geometry>
    </collision>
  </link>
  <joint
    name="left_knee"
    type="revolute">
    <origin
      xyz="0 -0.212 0"
      rpy="-3.1416 0 -3.1416" />
    <parent
      link="fix_left_femur2_2" />
    <child
      link="revolute_left_knee" />
    <axis
      xyz="0 0 1" />
    <limit
      lower="-2"
      upper="2"
      effort="5"
      velocity="10" />
  </joint>
  <link
    name="fix_lefttibia_1">
    <inertial>
      <origin
        xyz="-8.9841E-06 -0.21908 0.022299"
        rpy="0 0 0" />
      <mass
        value="0.058" />
      <inertia
        ixx="1.096E-05"
        ixy="-4.4082E-09"
        ixz="-5.2455E-09"
        iyy="6.3088E-06"
        iyz="-2.5553E-07"
        izz="9.8712E-06" />
    </inertial>
    <visual>
      <origin
        xyz="0 0 0"
        rpy="0 0 0" />
      <geometry>
        <mesh
          filename="file://$(find robot_bringup)/meshes/fix_lefttibia_1.STL" />
      </geometry>
      <material
        name="">
        <color
          rgba="0.25 0.25 0.25 1" />
      </material>
    </visual>
    <collision>
      <origin
        xyz="0 0 0"
        rpy="0 0 0" />
      <geometry>
        <mesh
          filename="file://$(find robot_bringup)/meshes/fix_lefttibia_1.STL" />
      </geometry>
    </collision>
  </link>
  <joint
    name="lefttibia_1"
    type="fixed">
    <origin
      xyz="0 0 0"
      rpy="0 0 0" />
    <parent
      link="revolute_left_knee" />
    <child
      link="fix_lefttibia_1" />
    <axis
      xyz="0 0 0" />
  </joint>
  <link
    name="revolute_leftfoot">
    <inertial>
      <origin
        xyz="-0.027568 -1.7471E-08 0.027995"
        rpy="0 0 0" />
      <mass
        value="0.05" />
      <inertia
        ixx="0.00011718"
        ixy="1.1251E-11"
        ixz="9.7855E-07"
        iyy="2.3664E-05"
        iyz="1.9493E-11"
        izz="0.00010381" />
    </inertial>
    <visual>
      <origin
        xyz="0 0 0"
        rpy="0 0 0" />
      <geometry>
        <mesh
          filename="file://$(find robot_bringup)/meshes/revolute_leftfoot.STL" />
      </geometry>
      <material
        name="">
        <color
          rgba="0.4 0.4 0.4 1" />
      </material>
    </visual>
    <collision>
      <origin
        xyz="0 0 0"
        rpy="0 0 0" />
      <geometry>
        <mesh
          filename="file://$(find robot_bringup)/meshes/revolute_leftfoot.STL" />
      </geometry>
    </collision>
  </link>
  <joint
    name="left_ankle"
    type="revolute">
    <origin
      xyz="0 -0.231 0.0025"
      rpy="0 0 1.5708" />
    <parent
      link="fix_lefttibia_1" />
    <child
      link="revolute_leftfoot" />
    <axis
      xyz="0 0 -1" />
    <limit
      lower="-1.732"
      upper="1.732"
      effort="1.5"
      velocity="10" />
  </joint>
  <link
    name="fix_lefttibia_2">
    <inertial>
      <origin
        xyz="3.6811E-15 -0.18991 0.0234"
        rpy="0 0 0" />
      <mass
        value="0.01" />
      <inertia
        ixx="8.4456E-07"
        ixy="-7.3819E-20"
        ixz="1.598E-13"
        iyy="1.1166E-06"
        iyz="9.6492E-20"
        izz="1.4884E-06" />
    </inertial>
    <visual>
      <origin
        xyz="0 0 0"
        rpy="0 0 0" />
      <geometry>
        <mesh
          filename="file://$(find robot_bringup)/meshes/fix_lefttibia_2.STL" />
      </geometry>
      <material
        name="">
        <color
          rgba="0.4 0.4 0.4 1" />
      </material>
    </visual>
    <collision>
      <origin
        xyz="0 0 0"
        rpy="0 0 0" />
      <geometry>
        <mesh
          filename="file://$(find robot_bringup)/meshes/fix_lefttibia_2.STL" />
      </geometry>
    </collision>
  </link>
  <joint
    name="lefttibia_2"
    type="fixed">
    <origin
      xyz="0 0 0"
      rpy="0 0 0" />
    <parent
      link="revolute_left_knee" />
    <child
      link="fix_lefttibia_2" />
    <axis
      xyz="0 0 0" />
  </joint>
  <link
    name="fix_lefttibia_3">
    <inertial>
      <origin
        xyz="-0.00077912 -0.1734 0.026003"
        rpy="0 0 0" />
      <mass
        value="0.0008" />
      <inertia
        ixx="8.7805E-08"
        ixy="7.0514E-23"
        ixz="8.4902E-09"
        iyy="1.4099E-07"
        iyz="-1.6789E-22"
        izz="6.0985E-08" />
    </inertial>
    <visual>
      <origin
        xyz="0 0 0"
        rpy="0 0 0" />
      <geometry>
        <mesh
          filename="file://$(find robot_bringup)/meshes/fix_lefttibia_3.STL" />
      </geometry>
      <material
        name="">
        <color
          rgba="0.5 0.5 0.5 1" />
      </material>
    </visual>
    <collision>
      <origin
        xyz="0 0 0"
        rpy="0 0 0" />
      <geometry>
        <mesh
          filename="file://$(find robot_bringup)/meshes/fix_lefttibia_3.STL" />
      </geometry>
    </collision>
  </link>
  <joint
    name="lefttibia_3"
    type="fixed">
    <origin
      xyz="0 0 0"
      rpy="0 0 0" />
    <parent
      link="revolute_left_knee" />
    <child
      link="fix_lefttibia_3" />
    <axis
      xyz="0 0 0" />
  </joint>
  <link
    name="fix_lefttibia_4">
    <inertial>
      <origin
        xyz="-5.3776E-17 -0.1155 0.0234"
        rpy="0 0 0" />
      <mass
        value="0.007" />
      <inertia
        ixx="7.9956E-06"
        ixy="-3.9879E-21"
        ixz="3.4897E-24"
        iyy="8.6944E-08"
        iyz="4.544E-21"
        izz="7.9956E-06" />
    </inertial>
    <visual>
      <origin
        xyz="0 0 0"
        rpy="0 0 0" />
      <geometry>
        <mesh
          filename="file://$(find robot_bringup)/meshes/fix_lefttibia_4.STL" />
      </geometry>
      <material
        name="">
        <color
          rgba="0.5 0.5 0.5 1" />
      </material>
    </visual>
    <collision>
      <origin
        xyz="0 0 0"
        rpy="0 0 0" />
      <geometry>
        <mesh
          filename="file://$(find robot_bringup)/meshes/fix_lefttibia_4.STL" />
      </geometry>
    </collision>
  </link>
  <joint
    name="lefttibia_4"
    type="fixed">
    <origin
      xyz="0 0 0"
      rpy="0 0 0" />
    <parent
      link="revolute_left_knee" />
    <child
      link="fix_lefttibia_4" />
    <axis
      xyz="0 0 0" />
  </joint>
  <link
    name="fix_lefttibia_5">
    <inertial>
      <origin
        xyz="3.8181E-15 -0.04109 0.0234"
        rpy="0 0 0" />
      <mass
        value="0.01" />
      <inertia
        ixx="8.4456E-07"
        ixy="7.5307E-20"
        ixz="-1.598E-13"
        iyy="1.1166E-06"
        iyz="9.6686E-20"
        izz="1.4884E-06" />
    </inertial>
    <visual>
      <origin
        xyz="0 0 0"
        rpy="0 0 0" />
      <geometry>
        <mesh
          filename="file://$(find robot_bringup)/meshes/fix_lefttibia_5.STL" />
      </geometry>
      <material
        name="">
        <color
          rgba="0.4 0.4 0.4 1" />
      </material>
    </visual>
    <collision>
      <origin
        xyz="0 0 0"
        rpy="0 0 0" />
      <geometry>
        <mesh
          filename="file://$(find robot_bringup)/meshes/fix_lefttibia_5.STL" />
      </geometry>
    </collision>
  </link>
  <joint
    name="lefttibia_5"
    type="fixed">
    <origin
      xyz="0 0 0"
      rpy="0 0 0" />
    <parent
      link="revolute_left_knee" />
    <child
      link="fix_lefttibia_5" />
    <axis
      xyz="0 0 0" />
  </joint>
  <link
    name="fix_lefttibia_6">
    <inertial>
      <origin
        xyz="2.949E-17 -0.00179 0.035364"
        rpy="0 0 0" />
      <mass
        value="0.004" />
      <inertia
        ixx="4.093E-07"
        ixy="2.8702E-22"
        ixz="-6.1979E-23"
        iyy="1.0855E-06"
        iyz="1.343E-09"
        izz="7.5439E-07" />
    </inertial>
    <visual>
      <origin
        xyz="0 0 0"
        rpy="0 0 0" />
      <geometry>
        <mesh
          filename="file://$(find robot_bringup)/meshes/fix_lefttibia_6.STL" />
      </geometry>
      <material
        name="">
        <color
          rgba="0.5 0.5 0.5 1" />
      </material>
    </visual>
    <collision>
      <origin
        xyz="0 0 0"
        rpy="0 0 0" />
      <geometry>
        <mesh
          filename="file://$(find robot_bringup)/meshes/fix_lefttibia_6.STL" />
      </geometry>
    </collision>
  </link>
  <joint
    name="lefttibia_6"
    type="fixed">
    <origin
      xyz="0 0 0"
      rpy="0 0 0" />
    <parent
      link="revolute_left_knee" />
    <child
      link="fix_lefttibia_6" />
    <axis
      xyz="0 0 0" />
  </joint>
  <link
    name="fix_left_femur2_3">
    <inertial>
      <origin
        xyz="2.8449E-16 -0.106 -0.0254"
        rpy="0 0 0" />
      <mass
        value="0.007" />
      <inertia
        ixx="7.9956E-06"
        ixy="1.1081E-20"
        ixz="6.2039E-24"
        iyy="8.6944E-08"
        iyz="-1.6661E-21"
        izz="7.9956E-06" />
    </inertial>
    <visual>
      <origin
        xyz="0 0 0"
        rpy="0 0 0" />
      <geometry>
        <mesh
          filename="file://$(find robot_bringup)/meshes/fix_left_femur2_3.STL" />
      </geometry>
      <material
        name="">
        <color
          rgba="0.5 0.5 0.5 1" />
      </material>
    </visual>
    <collision>
      <origin
        xyz="0 0 0"
        rpy="0 0 0" />
      <geometry>
        <mesh
          filename="file://$(find robot_bringup)/meshes/fix_left_femur2_3.STL" />
      </geometry>
    </collision>
  </link>
  <joint
    name="left_femur2_3"
    type="fixed">
    <origin
      xyz="0 0 0"
      rpy="0 0 0" />
    <parent
      link="revolute_left_femur2_1" />
    <child
      link="fix_left_femur2_3" />
    <axis
      xyz="0 0 0" />
  </joint>
  <link
    name="fix_femur1_3">
    <inertial>
      <origin
        xyz="0.048875 0.0066861 0.018792"
        rpy="0 0 0" />
      <mass
        value="0.008" />
      <inertia
        ixx="1.446E-06"
        ixy="-2.1079E-22"
        ixz="5.8169E-22"
        iyy="2.2684E-06"
        iyz="3.6652E-07"
        izz="2.2752E-06" />
    </inertial>
    <visual>
      <origin
        xyz="0 0 0"
        rpy="0 0 0" />
      <geometry>
        <mesh
          filename="file://$(find robot_bringup)/meshes/fix_femur1_3.STL" />
      </geometry>
      <material
        name="">
        <color
          rgba="0.5 0.5 0.5 1" />
      </material>
    </visual>
    <collision>
      <origin
        xyz="0 0 0"
        rpy="0 0 0" />
      <geometry>
        <mesh
          filename="file://$(find robot_bringup)/meshes/fix_femur1_3.STL" />
      </geometry>
    </collision>
  </link>
  <joint
    name="femur1_3"
    type="fixed">
    <origin
      xyz="0 0 0"
      rpy="0 0 0" />
    <parent
      link="revolute_left_femur1_1" />
    <child
      link="fix_femur1_3" />
    <axis
      xyz="0 0 0" />
  </joint>
  <link
    name="fix_femur1_4">
    <inertial>
      <origin
        xyz="-2.0817E-17 -1.1102E-16 0.0494"
        rpy="0 0 0" />
      <mass
        value="0.0003" />
      <inertia
        ixx="7.2605E-09"
        ixy="-4.3877E-24"
        ixz="-3.1443E-25"
        iyy="7.2605E-09"
        iyz="-8.4337E-25"
        izz="1.3645E-08" />
    </inertial>
    <visual>
      <origin
        xyz="0 0 0"
        rpy="0 0 0" />
      <geometry>
        <mesh
          filename="file://$(find robot_bringup)/meshes/fix_femur1_4.STL" />
      </geometry>
      <material
        name="">
        <color
          rgba="0.4 0.4 0.4 1" />
      </material>
    </visual>
    <collision>
      <origin
        xyz="0 0 0"
        rpy="0 0 0" />
      <geometry>
        <mesh
          filename="file://$(find robot_bringup)/meshes/fix_femur1_4.STL" />
      </geometry>
    </collision>
  </link>
  <joint
    name="femur1_4"
    type="fixed">
    <origin
      xyz="0 0 0"
      rpy="0 0 0" />
    <parent
      link="revolute_left_femur1_1" />
    <child
      link="fix_femur1_4" />
    <axis
      xyz="0 0 0" />
  </joint>
  <link
    name="fix_lefthip1motorbody">
    <inertial>
      <origin
        xyz="1.0408E-17 0.0093922 0.030086"
        rpy="0 0 0" />
      <mass
        value="0.008" />
      <inertia
        ixx="1.446E-06"
        ixy="-2.5537E-22"
        ixz="-3.0284E-22"
        iyy="2.2752E-06"
        iyz="3.6652E-07"
        izz="2.2684E-06" />
    </inertial>
    <visual>
      <origin
        xyz="0 0 0"
        rpy="0 0 0" />
      <geometry>
        <mesh
          filename="file://$(find robot_bringup)/meshes/fix_lefthip1motorbody.STL" />
      </geometry>
      <material
        name="">
        <color
          rgba="0.5 0.5 0.5 1" />
      </material>
    </visual>
    <collision>
      <origin
        xyz="0 0 0"
        rpy="0 0 0" />
      <geometry>
        <mesh
          filename="file://$(find robot_bringup)/meshes/fix_lefthip1motorbody.STL" />
      </geometry>
    </collision>
  </link>
  <joint
    name="lefthip1motorbody"
    type="fixed">
    <origin
      xyz="-0.0234 -0.11425 -0.024125"
      rpy="0 1.5707963267949 0" />
    <parent
      link="fix_leftlegtobaselink" />
    <child
      link="fix_lefthip1motorbody" />
    <axis
      xyz="0 0 0" />
  </joint>
  <link
    name="fix_rightlegtobaselink">
    <inertial>
      <origin
        xyz="-3.1196E-09 0.079316 0.0042205"
        rpy="0 0 0" />
      <mass
        value="0.028" />
      <inertia
        ixx="8.1588E-06"
        ixy="-1.3085E-13"
        ixz="4.33E-11"
        iyy="7.7241E-06"
        iyz="9.9424E-07"
        izz="8.6259E-06" />
    </inertial>
    <visual>
      <origin
        xyz="0 0 0"
        rpy="0 0 0" />
      <geometry>
        <mesh
          filename="file://$(find robot_bringup)/meshes/fix_rightlegtobaselink.STL" />
      </geometry>
      <material
        name="">
        <color
          rgba="0.5 0.5 0.5 1" />
      </material>
    </visual>
    <collision>
      <origin
        xyz="0 0 0"
        rpy="0 0 0" />
      <geometry>
        <mesh
          filename="file://$(find robot_bringup)/meshes/fix_rightlegtobaselink.STL" />
      </geometry>
    </collision>
  </link>
  <joint
    name="rightlegtobaselink"
    type="fixed">
    <origin
      xyz="0 0 0"
      rpy="0 0 0" />
    <parent
      link="base_link" />
    <child
      link="fix_rightlegtobaselink" />
    <axis
      xyz="0 0 0" />
  </joint>
  <link
    name="fix_righthip1towaist">
    <inertial>
      <origin
        xyz="-0.0030908 0.10376 -0.020982"
        rpy="0 0 0" />
      <mass
        value="0.08" />
      <inertia
        ixx="1.0361E-05"
        ixy="2.2331E-07"
        ixz="2.3379E-17"
        iyy="6.7254E-06"
        iyz="-2.8598E-14"
        izz="1.1542E-05" />
    </inertial>
    <visual>
      <origin
        xyz="0 0 0"
        rpy="0 0 0" />
      <geometry>
        <mesh
          filename="file://$(find robot_bringup)/meshes/fix_righthip1towaist.STL" />
      </geometry>
      <material
        name="">
        <color
          rgba="0.25 0.25 0.25 1" />
      </material>
    </visual>
    <collision>
      <origin
        xyz="0 0 0"
        rpy="0 0 0" />
      <geometry>
        <mesh
          filename="file://$(find robot_bringup)/meshes/fix_righthip1towaist.STL" />
      </geometry>
    </collision>
  </link>
  <joint
    name="righthip1towaist"
    type="fixed">
    <origin
      xyz="0 0 0"
      rpy="0 0 0" />
    <parent
      link="fix_rightlegtobaselink" />
    <child
      link="fix_righthip1towaist" />
    <axis
      xyz="0 0 0" />
  </joint>
  <link
    name="revolute_rightfemer1_1">
    <inertial>
      <origin
        xyz="1.3878E-17 -0.019235 0.026145"
        rpy="0 0 0" />
      <mass
        value="0.016" />
      <inertia
        ixx="5.4156E-06"
        ixy="2.3576E-22"
        ixz="-1.4877E-22"
        iyy="4.4847E-06"
        iyz="-2.5399E-07"
        izz="1.6499E-06" />
    </inertial>
    <visual>
      <origin
        xyz="0 0 0"
        rpy="0 0 0" />
      <geometry>
        <mesh
          filename="file://$(find robot_bringup)/meshes/revolute_rightfemer1_1.STL" />
      </geometry>
      <material
        name="">
        <color
          rgba="0.4 0.4 0.4 1" />
      </material>
    </visual>
    <collision>
      <origin
        xyz="0 0 0"
        rpy="0 0 0" />
      <geometry>
        <mesh
          filename="file://$(find robot_bringup)/meshes/revolute_rightfemer1_1.STL" />
      </geometry>
    </collision>
  </link>
  <joint
    name="right_hip1"
    type="revolute">
    <origin
      xyz="-0.02568 0.1157 -0.020982"
      rpy="1.5708 0 1.5708" />
    <parent
      link="fix_righthip1towaist" />
    <child
      link="revolute_rightfemer1_1" />
    <axis
      xyz="0 0 -1" />
    <limit
      lower="-1.732"
      upper="1.732"
      effort="3.7"
      velocity="10" />
  </joint>
  <link
    name="fix_right_femer1_2">
    <inertial>
      <origin
        xyz="0.00081105 -0.048875 0.021339"
        rpy="0 0 0" />
      <mass
        value="0.08" />
      <inertia
        ixx="1.0361E-05"
        ixy="2.3368E-17"
        ixz="2.2331E-07"
        iyy="1.1542E-05"
        iyz="-2.8598E-14"
        izz="6.7254E-06" />
    </inertial>
    <visual>
      <origin
        xyz="0 0 0"
        rpy="0 0 0" />
      <geometry>
        <mesh
          filename="file://$(find robot_bringup)/meshes/fix_right_femer1_2.STL" />
      </geometry>
      <material
        name="">
        <color
          rgba="0.25 0.25 0.25 1" />
      </material>
    </visual>
    <collision>
      <origin
        xyz="0 0 0"
        rpy="0 0 0" />
      <geometry>
        <mesh
          filename="file://$(find robot_bringup)/meshes/fix_right_femer1_2.STL" />
      </geometry>
    </collision>
  </link>
  <joint
    name="rightfemer1_2"
    type="fixed">
    <origin
      xyz="0 0 0"
      rpy="0 0 0" />
    <parent
      link="revolute_rightfemer1_1" />
    <child
      link="fix_right_femer1_2" />
    <axis
      xyz="0 0 0" />
  </joint>
  <link
    name="revolute_right_femur2_1">
    <inertial>
      <origin
        xyz="-1.5434E-11 -0.024976 -0.025952"
        rpy="0 0 0" />
      <mass
        value="0.016" />
      <inertia
        ixx="7.0717E-06"
        ixy="-1.5333E-15"
        ixz="2.8537E-12"
        iyy="4.694E-06"
        iyz="2.9746E-07"
        izz="3.2637E-06" />
    </inertial>
    <visual>
      <origin
        xyz="0 0 0"
        rpy="0 0 0" />
      <geometry>
        <mesh
          filename="file://$(find robot_bringup)/meshes/revolute_right_femur2_1.STL" />
      </geometry>
      <material
        name="">
        <color
          rgba="0.4 0.4 0.4 1" />
      </material>
    </visual>
    <collision>
      <origin
        xyz="0 0 0"
        rpy="0 0 0" />
      <geometry>
        <mesh
          filename="file://$(find robot_bringup)/meshes/revolute_right_femur2_1.STL" />
      </geometry>
    </collision>
  </link>
  <joint
    name="right_hip2"
    type="revolute">
    <origin
      xyz="0.0234 -0.048875 0.0094"
      rpy="0 1.5708 0" />
    <parent
      link="fix_right_femer1_2" />
    <child
      link="revolute_right_femur2_1" />
    <axis
      xyz="0 0 -1" />
    <limit
      lower="-1.732"
      upper="1.732"
      effort="3.7"
      velocity="10" />
  </joint>
  <link
    name="fix_right_femur2_2">
    <inertial>
      <origin
        xyz="1.5434E-11 -0.18702 -0.025952"
        rpy="0 0 0" />
      <mass
        value="0.016" />
      <inertia
        ixx="7.0717E-06"
        ixy="-1.5333E-15"
        ixz="-2.8537E-12"
        iyy="4.694E-06"
        iyz="-2.9746E-07"
        izz="3.2637E-06" />
    </inertial>
    <visual>
      <origin
        xyz="0 0 0"
        rpy="0 0 0" />
      <geometry>
        <mesh
          filename="file://$(find robot_bringup)/meshes/fix_right_femur2_2.STL" />
      </geometry>
      <material
        name="">
        <color
          rgba="0.4 0.4 0.4 1" />
      </material>
    </visual>
    <collision>
      <origin
        xyz="0 0 0"
        rpy="0 0 0" />
      <geometry>
        <mesh
          filename="file://$(find robot_bringup)/meshes/fix_right_femur2_2.STL" />
      </geometry>
    </collision>
  </link>
  <joint
    name="right_femur2_2"
    type="fixed">
    <origin
      xyz="0 0 0"
      rpy="0 0 0" />
    <parent
      link="revolute_right_femur2_1" />
    <child
      link="fix_right_femur2_2" />
    <axis
      xyz="0 0 0" />
  </joint>
  <link
    name="revolute_right_knee">
    <inertial>
      <origin
        xyz="-6.9708E-13 -0.011939 -0.022589"
        rpy="0 0 0" />
      <mass
        value="0.08" />
      <inertia
        ixx="1.1542E-05"
        ixy="-2.8598E-14"
        ixz="-2.3378E-17"
        iyy="6.7254E-06"
        iyz="-2.2331E-07"
        izz="1.0361E-05" />
    </inertial>
    <visual>
      <origin
        xyz="0 0 0"
        rpy="0 0 0" />
      <geometry>
        <mesh
          filename="file://$(find robot_bringup)/meshes/revolute_right_knee.STL" />
      </geometry>
      <material
        name="">
        <color
          rgba="0.25 0.25 0.25 1" />
      </material>
    </visual>
    <collision>
      <origin
        xyz="0 0 0"
        rpy="0 0 0" />
      <geometry>
        <mesh
          filename="file://$(find robot_bringup)/meshes/revolute_right_knee.STL" />
      </geometry>
    </collision>
  </link>
  <joint
    name="right_knee"
    type="revolute">
    <origin
      xyz="0 -0.212 0"
      rpy="0 0 0" />
    <parent
      link="fix_right_femur2_2" />
    <child
      link="revolute_right_knee" />
    <axis
      xyz="0 0 -1" />
    <limit
      lower="-2"
      upper="2"
      effort="5"
      velocity="10" />
  </joint>
  <link
    name="fix_righttibia_1">
    <inertial>
      <origin
        xyz="8.9841E-06 -0.21908 -0.022299"
        rpy="0 0 0" />
      <mass
        value="0.058" />
      <inertia
        ixx="1.096E-05"
        ixy="4.4082E-09"
        ixz="-5.2455E-09"
        iyy="6.3088E-06"
        iyz="2.5553E-07"
        izz="9.8712E-06" />
    </inertial>
    <visual>
      <origin
        xyz="0 0 0"
        rpy="0 0 0" />
      <geometry>
        <mesh
          filename="file://$(find robot_bringup)/meshes/fix_righttibia_1.STL" />
      </geometry>
      <material
        name="">
        <color
          rgba="0.25 0.25 0.25 1" />
      </material>
    </visual>
    <collision>
      <origin
        xyz="0 0 0"
        rpy="0 0 0" />
      <geometry>
        <mesh
          filename="file://$(find robot_bringup)/meshes/fix_righttibia_1.STL" />
      </geometry>
    </collision>
  </link>
  <joint
    name="righttibia_1"
    type="fixed">
    <origin
      xyz="0 0 0"
      rpy="0 0 0" />
    <parent
      link="revolute_right_knee" />
    <child
      link="fix_righttibia_1" />
    <axis
      xyz="0 0 0" />
  </joint>
  <link
    name="revolute_rightfoot">
    <inertial>
      <origin
        xyz="-1.7471E-08 -0.027568 -0.027995"
        rpy="0 0 0" />
      <mass
        value="0.05" />
      <inertia
        ixx="2.3664E-05"
        ixy="1.1251E-11"
        ixz="-1.9493E-11"
        iyy="0.00011718"
        iyz="-9.7855E-07"
        izz="0.00010381" />
    </inertial>
    <visual>
      <origin
        xyz="0 0 0"
        rpy="0 0 0" />
      <geometry>
        <mesh
          filename="file://$(find robot_bringup)/meshes/revolute_rightfoot.STL" />
      </geometry>
      <material
        name="">
        <color
          rgba="0.4 0.4 0.4 1" />
      </material>
    </visual>
    <collision>
      <origin
        xyz="0 0 0"
        rpy="0 0 0" />
      <geometry>
        <mesh
          filename="file://$(find robot_bringup)/meshes/revolute_rightfoot.STL" />
      </geometry>
    </collision>
  </link>
  <joint
    name="right_ankle"
    type="revolute">
    <origin
      xyz="0 -0.231 -0.0025"
      rpy="0 0 0" />
    <parent
      link="fix_righttibia_1" />
    <child
      link="revolute_rightfoot" />
    <axis
      xyz="0 0 -1" />
    <limit
      lower="-1.732"
      upper="1.732"
      effort="1.5"
      velocity="10" />
  </joint>
  <link
    name="fix_righttibia_2">
    <inertial>
      <origin
        xyz="-3.6915E-15 -0.18991 -0.0234"
        rpy="0 0 0" />
      <mass
        value="0.01" />
      <inertia
        ixx="8.4456E-07"
        ixy="7.5448E-20"
        ixz="1.598E-13"
        iyy="1.1166E-06"
        iyz="-9.7142E-20"
        izz="1.4884E-06" />
    </inertial>
    <visual>
      <origin
        xyz="0 0 0"
        rpy="0 0 0" />
      <geometry>
        <mesh
          filename="file://$(find robot_bringup)/meshes/fix_righttibia_2.STL" />
      </geometry>
      <material
        name="">
        <color
          rgba="0.4 0.4 0.4 1" />
      </material>
    </visual>
    <collision>
      <origin
        xyz="0 0 0"
        rpy="0 0 0" />
      <geometry>
        <mesh
          filename="file://$(find robot_bringup)/meshes/fix_righttibia_2.STL" />
      </geometry>
    </collision>
  </link>
  <joint
    name="righttibia_2"
    type="fixed">
    <origin
      xyz="0 0 0"
      rpy="0 0 0" />
    <parent
      link="revolute_right_knee" />
    <child
      link="fix_righttibia_2" />
    <axis
      xyz="0 0 0" />
  </joint>
  <link
    name="fix_righttibia_3">
    <inertial>
      <origin
        xyz="0.00077912 -0.1734 -0.026003"
        rpy="0 0 0" />
      <mass
        value="0.0008" />
      <inertia
        ixx="8.7805E-08"
        ixy="7.2804E-23"
        ixz="8.4902E-09"
        iyy="1.4099E-07"
        iyz="3.7197E-23"
        izz="6.0985E-08" />
    </inertial>
    <visual>
      <origin
        xyz="0 0 0"
        rpy="0 0 0" />
      <geometry>
        <mesh
          filename="file://$(find robot_bringup)/meshes/fix_righttibia_3.STL" />
      </geometry>
      <material
        name="">
        <color
          rgba="0.5 0.5 0.5 1" />
      </material>
    </visual>
    <collision>
      <origin
        xyz="0 0 0"
        rpy="0 0 0" />
      <geometry>
        <mesh
          filename="file://$(find robot_bringup)/meshes/fix_righttibia_3.STL" />
      </geometry>
    </collision>
  </link>
  <joint
    name="righttibia_3"
    type="fixed">
    <origin
      xyz="0 0 0"
      rpy="0 0 0" />
    <parent
      link="revolute_right_knee" />
    <child
      link="fix_righttibia_3" />
    <axis
      xyz="0 0 0" />
  </joint>
  <link
    name="fix_righttibia_4">
    <inertial>
      <origin
        xyz="2.0817E-17 -0.1155 -0.0234"
        rpy="0 0 0" />
      <mass
        value="0.007" />
      <inertia
        ixx="7.9956E-06"
        ixy="-2.1419E-21"
        ixz="2.068E-24"
        iyy="8.6944E-08"
        iyz="-1.2023E-20"
        izz="7.9956E-06" />
    </inertial>
    <visual>
      <origin
        xyz="0 0 0"
        rpy="0 0 0" />
      <geometry>
        <mesh
          filename="file://$(find robot_bringup)/meshes/fix_righttibia_4.STL" />
      </geometry>
      <material
        name="">
        <color
          rgba="0.5 0.5 0.5 1" />
      </material>
    </visual>
    <collision>
      <origin
        xyz="0 0 0"
        rpy="0 0 0" />
      <geometry>
        <mesh
          filename="file://$(find robot_bringup)/meshes/fix_righttibia_4.STL" />
      </geometry>
    </collision>
  </link>
  <joint
    name="righttibia_4"
    type="fixed">
    <origin
      xyz="0 0 0"
      rpy="0 0 0" />
    <parent
      link="revolute_right_knee" />
    <child
      link="fix_righttibia_4" />
    <axis
      xyz="0 0 0" />
  </joint>
  <link
    name="fix_righttibia_5">
    <inertial>
      <origin
        xyz="-3.8025E-15 -0.04109 -0.0234"
        rpy="0 0 0" />
      <mass
        value="0.01" />
      <inertia
        ixx="8.4456E-07"
        ixy="-7.4895E-20"
        ixz="-1.598E-13"
        iyy="1.1166E-06"
        iyz="-9.6616E-20"
        izz="1.4884E-06" />
    </inertial>
    <visual>
      <origin
        xyz="0 0 0"
        rpy="0 0 0" />
      <geometry>
        <mesh
          filename="file://$(find robot_bringup)/meshes/fix_righttibia_5.STL" />
      </geometry>
      <material
        name="">
        <color
          rgba="0.4 0.4 0.4 1" />
      </material>
    </visual>
    <collision>
      <origin
        xyz="0 0 0"
        rpy="0 0 0" />
      <geometry>
        <mesh
          filename="file://$(find robot_bringup)/meshes/fix_righttibia_5.STL" />
      </geometry>
    </collision>
  </link>
  <joint
    name="righttibia_5"
    type="fixed">
    <origin
      xyz="0 0 0"
      rpy="0 0 0" />
    <parent
      link="revolute_right_knee" />
    <child
      link="fix_righttibia_5" />
    <axis
      xyz="0 0 0" />
  </joint>
  <link
    name="fix_righttibia_6">
    <inertial>
      <origin
        xyz="-6.9389E-18 -0.00179 -0.035364"
        rpy="0 0 0" />
      <mass
        value="0.004" />
      <inertia
        ixx="4.093E-07"
        ixy="-5.7608E-22"
        ixz="-5.1866E-22"
        iyy="1.0855E-06"
        iyz="-1.343E-09"
        izz="7.5439E-07" />
    </inertial>
    <visual>
      <origin
        xyz="0 0 0"
        rpy="0 0 0" />
      <geometry>
        <mesh
          filename="file://$(find robot_bringup)/meshes/fix_righttibia_6.STL" />
      </geometry>
      <material
        name="">
        <color
          rgba="0.5 0.5 0.5 1" />
      </material>
    </visual>
    <collision>
      <origin
        xyz="0 0 0"
        rpy="0 0 0" />
      <geometry>
        <mesh
          filename="file://$(find robot_bringup)/meshes/fix_righttibia_6.STL" />
      </geometry>
    </collision>
  </link>
  <joint
    name="righttibia_6"
    type="fixed">
    <origin
      xyz="0 0 0"
      rpy="0 0 0" />
    <parent
      link="revolute_right_knee" />
    <child
      link="fix_righttibia_6" />
    <axis
      xyz="0 0 0" />
  </joint>
  <link
    name="fix_right_femur2_3">
    <inertial>
      <origin
        xyz="2.3939E-16 -0.106 -0.0254"
        rpy="0 0 0" />
      <mass
        value="0.007" />
      <inertia
        ixx="7.9956E-06"
        ixy="-3.3326E-21"
        ixz="1.8353E-23"
        iyy="8.6944E-08"
        iyz="2.3569E-21"
        izz="7.9956E-06" />
    </inertial>
    <visual>
      <origin
        xyz="0 0 0"
        rpy="0 0 0" />
      <geometry>
        <mesh
          filename="file://$(find robot_bringup)/meshes/fix_right_femur2_3.STL" />
      </geometry>
      <material
        name="">
        <color
          rgba="0.5 0.5 0.5 1" />
      </material>
    </visual>
    <collision>
      <origin
        xyz="0 0 0"
        rpy="0 0 0" />
      <geometry>
        <mesh
          filename="file://$(find robot_bringup)/meshes/fix_right_femur2_3.STL" />
      </geometry>
    </collision>
  </link>
  <joint
    name="right_femur2_3"
    type="fixed">
    <origin
      xyz="0 0 0"
      rpy="0 0 0" />
    <parent
      link="revolute_right_femur2_1" />
    <child
      link="fix_right_femur2_3" />
    <axis
      xyz="0 0 0" />
  </joint>
  <link
    name="fix_rightfemer1_3">
    <inertial>
      <origin
        xyz="-0.0066861 -0.048875 0.018792"
        rpy="0 0 0" />
      <mass
        value="0.008" />
      <inertia
        ixx="2.2684E-06"
        ixy="-7.3366E-22"
        ixz="-3.6652E-07"
        iyy="1.446E-06"
        iyz="-5.192E-22"
        izz="2.2752E-06" />
    </inertial>
    <visual>
      <origin
        xyz="0 0 0"
        rpy="0 0 0" />
      <geometry>
        <mesh
          filename="file://$(find robot_bringup)/meshes/fix_rightfemer1_3.STL" />
      </geometry>
      <material
        name="">
        <color
          rgba="0.5 0.5 0.5 1" />
      </material>
    </visual>
    <collision>
      <origin
        xyz="0 0 0"
        rpy="0 0 0" />
      <geometry>
        <mesh
          filename="file://$(find robot_bringup)/meshes/fix_rightfemer1_3.STL" />
      </geometry>
    </collision>
  </link>
  <joint
    name="rightfemer1_3"
    type="fixed">
    <origin
      xyz="0 0 0"
      rpy="0 0 0" />
    <parent
      link="revolute_rightfemer1_1" />
    <child
      link="fix_rightfemer1_3" />
    <axis
      xyz="0 0 0" />
  </joint>
  <link
    name="fix_rightfemer1_4">
    <inertial>
      <origin
        xyz="-2.7756E-17 4.5103E-17 0.0494"
        rpy="0 0 0" />
      <mass
        value="0.0003" />
      <inertia
        ixx="7.2605E-09"
        ixy="2.4382E-24"
        ixz="-3.3036E-26"
        iyy="7.2605E-09"
        iyz="-7.6587E-25"
        izz="1.3645E-08" />
    </inertial>
    <visual>
      <origin
        xyz="0 0 0"
        rpy="0 0 0" />
      <geometry>
        <mesh
          filename="file://$(find robot_bringup)/meshes/fix_rightfemer1_4.STL" />
      </geometry>
      <material
        name="">
        <color
          rgba="0.5 0.5 0.5 1" />
      </material>
    </visual>
    <collision>
      <origin
        xyz="0 0 0"
        rpy="0 0 0" />
      <geometry>
        <mesh
          filename="file://$(find robot_bringup)/meshes/fix_rightfemer1_4.STL" />
      </geometry>
    </collision>
  </link>
  <joint
    name="rightfemer1_4"
    type="fixed">
    <origin
      xyz="0 0 0"
      rpy="0 0 0" />
    <parent
      link="revolute_rightfemer1_1" />
    <child
      link="fix_rightfemer1_4" />
    <axis
      xyz="0 0 0" />
  </joint>
  <link
    name="fix_right_hip1motorbody">
    <inertial>
      <origin
        xyz="0.0044063 0.10631 -0.020982"
        rpy="0 0 0" />
      <mass
        value="0.008" />
      <inertia
        ixx="2.2684E-06"
        ixy="-3.6652E-07"
        ixz="3.3557E-22"
        iyy="2.2752E-06"
        iyz="1.3715E-22"
        izz="1.446E-06" />
    </inertial>
    <visual>
      <origin
        xyz="0 0 0"
        rpy="0 0 0" />
      <geometry>
        <mesh
          filename="file://$(find robot_bringup)/meshes/fix_right_hip1motorbody.STL" />
      </geometry>
      <material
        name="">
        <color
          rgba="0.5 0.5 0.5 1" />
      </material>
    </visual>
    <collision>
      <origin
        xyz="0 0 0"
        rpy="0 0 0" />
      <geometry>
        <mesh
          filename="file://$(find robot_bringup)/meshes/fix_right_hip1motorbody.STL" />
      </geometry>
    </collision>
  </link>
  <joint
    name="right_hip1motorbody"
    type="fixed">
    <origin
      xyz="0 0 0"
      rpy="0 0 0" />
    <parent
      link="fix_rightlegtobaselink" />
    <child
      link="fix_right_hip1motorbody" />
    <axis
      xyz="0 0 0" />
  </joint>
  <link
    name="fix_torsotobaselink1">
    <inertial>
      <origin
        xyz="-0.0012031 8.5344E-19 0.024015"
        rpy="0 0 0" />
      <mass
        value="0.02" />
      <inertia
        ixx="5.3699E-06"
        ixy="-2.5534E-21"
        ixz="4.9395E-07"
        iyy="1.0212E-05"
        iyz="6.4627E-21"
        izz="1.098E-05" />
    </inertial>
    <visual>
      <origin
        xyz="0 0 0"
        rpy="0 0 0" />
      <geometry>
        <mesh
          filename="file://$(find robot_bringup)/meshes/fix_torsotobaselink1.STL" />
      </geometry>
      <material
        name="">
        <color
          rgba="0.5 0.5 0.5 1" />
      </material>
    </visual>
    <collision>
      <origin
        xyz="0 0 0"
        rpy="0 0 0" />
      <geometry>
        <mesh
          filename="file://$(find robot_bringup)/meshes/fix_torsotobaselink1.STL" />
      </geometry>
    </collision>
  </link>
  <joint
    name="torsotobaselink1"
    type="fixed">
    <origin
      xyz="0 0 0"
      rpy="0 0 0" />
    <parent
      link="base_link" />
    <child
      link="fix_torsotobaselink1" />
    <axis
      xyz="0 0 0" />
  </joint>
  <link
    name="servo1">
    <inertial>
      <origin
        xyz="-7.7571E-11 0.015029 -0.029118"
        rpy="0 0 0" />
      <mass
        value="0.165" />
      <inertia
        ixx="3.834E-05"
        ixy="4.775E-14"
        ixz="-8.2973E-14"
        iyy="2.1548E-05"
        iyz="1.6188E-07"
        izz="3.1728E-05" />
    </inertial>
    <visual>
      <origin
        xyz="0 0 0"
        rpy="0 0 0" />
      <geometry>
        <mesh
          filename="file://$(find robot_bringup)/meshes/servo1.STL" />
      </geometry>
      <material
        name="">
        <color
          rgba="0.25 0.25 0.25 1" />
      </material>
    </visual>
    <collision>
      <origin
        xyz="0 0 0"
        rpy="0 0 0" />
      <geometry>
        <mesh
          filename="file://$(find robot_bringup)/meshes/servo1.STL" />
      </geometry>
    </collision>
  </link>
  <joint
    name="torso"
    type="revolute">
    <origin
      xyz="0.0298 0 0.04225"
      rpy="1.5708 0 1.5708" />
    <parent
      link="fix_torsotobaselink1" />
    <child
      link="servo1" />
    <axis
      xyz="0 0 1" />
    <limit
      lower="-1.732"
      upper="1.732"
      effort="13"
      velocity="10" />
  </joint>
  <link
    name="fix_torsolink1">
    <inertial>
      <origin
        xyz="-0.00015 0.049553 -0.0298"
        rpy="0 0 0" />
      <mass
        value="0.011" />
      <inertia
        ixx="1.0537E-06"
        ixy="1.3748E-22"
        ixz="8.0242E-15"
        iyy="1.857E-06"
        iyz="-1.2961E-22"
        izz="2.1198E-06" />
    </inertial>
    <visual>
      <origin
        xyz="0 0 0"
        rpy="0 0 0" />
      <geometry>
        <mesh
          filename="file://$(find robot_bringup)/meshes/fix_torsolink1.STL" />
      </geometry>
      <material
        name="">
        <color
          rgba="0.4 0.4 0.4 1" />
      </material>
    </visual>
    <collision>
      <origin
        xyz="0 0 0"
        rpy="0 0 0" />
      <geometry>
        <mesh
          filename="file://$(find robot_bringup)/meshes/fix_torsolink1.STL" />
      </geometry>
    </collision>
  </link>
  <joint
    name="torsolink1"
    type="fixed">
    <origin
      xyz="0 0 0"
      rpy="0 0 0" />
    <parent
      link="servo1" />
    <child
      link="fix_torsolink1" />
    <axis
      xyz="0 0 0" />
  </joint>
  <link
    name="fix_torsolink2">
    <inertial>
      <origin
        xyz="-0.00015 0.20875 -0.0298"
        rpy="0 0 0" />
      <mass
        value="0.015" />
      <inertia
        ixx="5.848E-05"
        ixy="-5.1101E-21"
        ixz="-9.0783E-24"
        iyy="1.4923E-07"
        iyz="-1.4156E-19"
        izz="5.848E-05" />
    </inertial>
    <visual>
      <origin
        xyz="0 0 0"
        rpy="0 0 0" />
      <geometry>
        <mesh
          filename="file://$(find robot_bringup)/meshes/fix_torsolink2.STL" />
      </geometry>
      <material
        name="">
        <color
          rgba="0.5 0.5 0.5 1" />
      </material>
    </visual>
    <collision>
      <origin
        xyz="0 0 0"
        rpy="0 0 0" />
      <geometry>
        <mesh
          filename="file://$(find robot_bringup)/meshes/fix_torsolink2.STL" />
      </geometry>
    </collision>
  </link>
  <joint
    name="torsolink2"
    type="fixed">
    <origin
      xyz="0 0 0"
      rpy="0 0 0" />
    <parent
      link="servo1" />
    <child
      link="fix_torsolink2" />
    <axis
      xyz="0 0 0" />
  </joint>
  <link
    name="fix_torsolink3">
    <inertial>
      <origin
        xyz="-0.00015 0.36452 -0.0298"
        rpy="0 0 0" />
      <mass
        value="0.007" />
      <inertia
        ixx="6.0919E-07"
        ixy="1.356E-22"
        ixz="1.2785E-17"
        iyy="5.457E-07"
        iyz="-2.5117E-22"
        izz="7.0719E-07" />
    </inertial>
    <visual>
      <origin
        xyz="0 0 0"
        rpy="0 0 0" />
      <geometry>
        <mesh
          filename="file://$(find robot_bringup)/meshes/fix_torsolink3.STL" />
      </geometry>
      <material
        name="">
        <color
          rgba="0.4 0.4 0.4 1" />
      </material>
    </visual>
    <collision>
      <origin
        xyz="0 0 0"
        rpy="0 0 0" />
      <geometry>
        <mesh
          filename="file://$(find robot_bringup)/meshes/fix_torsolink3.STL" />
      </geometry>
    </collision>
  </link>
  <joint
    name="torsolink3"
    type="fixed">
    <origin
      xyz="0 0 0"
      rpy="0 0 0" />
    <parent
      link="servo1" />
    <child
      link="fix_torsolink3" />
    <axis
      xyz="0 0 0" />
  </joint>
  <link
    name="fix_torsoweight">
    <inertial>
      <origin
        xyz="-0.00015 0.37425 -0.0298"
        rpy="0 0 0" />
      <mass
        value="0.22" />
      <inertia
        ixx="2.2936E-05"
        ixy="-1.0029E-21"
        ixz="3.3363E-22"
        iyy="4.5838E-05"
        iyz="5.2146E-20"
        izz="2.2933E-05" />
    </inertial>
    <visual>
      <origin
        xyz="0 0 0"
        rpy="0 0 0" />
      <geometry>
        <mesh
          filename="file://$(find robot_bringup)/meshes/fix_torsoweight.STL" />
      </geometry>
      <material
        name="">
        <color
          rgba="0.5 0.5 0.5 1" />
      </material>
    </visual>
    <collision>
      <origin
        xyz="0 0 0"
        rpy="0 0 0" />
      <geometry>
        <mesh
          filename="file://$(find robot_bringup)/meshes/fix_torsoweight.STL" />
      </geometry>
    </collision>
  </link>
  <joint
    name="torsoweight"
    type="fixed">
    <origin
      xyz="0 0 0"
      rpy="0 0 0" />
    <parent
      link="servo1" />
    <child
      link="fix_torsoweight" />
    <axis
      xyz="0 0 0" />
  </joint>
  <link
    name="fix_torsotobaselink2">
    <inertial>
      <origin
        xyz="-2.317E-18 7.7378E-18 0.01875"
        rpy="0 0 0" />
      <mass
        value="0.008" />
      <inertia
        ixx="2.331E-06"
        ixy="-1.5607E-21"
        ixz="-5.911E-23"
        iyy="1.9323E-06"
        iyz="5.3201E-22"
        izz="4.2505E-06" />
    </inertial>
    <visual>
      <origin
        xyz="0 0 0"
        rpy="0 0 0" />
      <geometry>
        <mesh
          filename="file://$(find robot_bringup)/meshes/fix_torsotobaselink2.STL" />
      </geometry>
      <material
        name="">
        <color
          rgba="0.5 0.5 0.5 1" />
      </material>
    </visual>
    <collision>
      <origin
        xyz="0 0 0"
        rpy="0 0 0" />
      <geometry>
        <mesh
          filename="file://$(find robot_bringup)/meshes/fix_torsotobaselink2.STL" />
      </geometry>
    </collision>
  </link>
  <joint
    name="torsotobaselink"
    type="fixed">
    <origin
      xyz="0 0 0"
      rpy="0 0 0" />
    <parent
      link="base_link" />
    <child
      link="fix_torsotobaselink2" />
    <axis
      xyz="0 0 0" />
  </joint>
  <link
    name="fix_cfpipe1tobaselink">
    <inertial>
      <origin
        xyz="0.01375 1.8352E-17 0.00925"
        rpy="0 0 0" />
      <mass
        value="0.007" />
      <inertia
        ixx="6.165E-06"
        ixy="1.8956E-37"
        ixz="0"
        iyy="7.039E-08"
        iyz="1.422E-21"
        izz="6.165E-06" />
    </inertial>
    <visual>
      <origin
        xyz="0 0 0"
        rpy="0 0 0" />
      <geometry>
        <mesh
          filename="file://$(find robot_bringup)/meshes/fix_cfpipe1tobaselink.STL" />
      </geometry>
      <material
        name="">
        <color
          rgba="0.5 0.5 0.5 1" />
      </material>
    </visual>
    <collision>
      <origin
        xyz="0 0 0"
        rpy="0 0 0" />
      <geometry>
        <mesh
          filename="file://$(find robot_bringup)/meshes/fix_cfpipe1tobaselink.STL" />
      </geometry>
    </collision>
  </link>
  <joint
    name="cfpipe1tobaselink"
    type="fixed">
    <origin
      xyz="0 0 0"
      rpy="0 0 0" />
    <parent
      link="base_link" />
    <child
      link="fix_cfpipe1tobaselink" />
    <axis
      xyz="0 0 0" />
  </joint>
  <link
    name="fix_cfpipe2tobaselink">
    <inertial>
      <origin
        xyz="0 0 0"
        rpy="0 0 0" />
      <mass
        value="0.007" />
      <inertia
        ixx="0"
        ixy="0"
        ixz="0"
        iyy="0"
        iyz="0"
        izz="0" />
    </inertial>
    <visual>
      <origin
        xyz="0 0 0"
        rpy="0 0 0" />
      <geometry>
        <mesh
          filename="file://$(find robot_bringup)/meshes/fix_cfpipe2tobaselink.STL" />
      </geometry>
      <material
        name="">
        <color
          rgba="0.5 0.5 0.5 1" />
      </material>
    </visual>
    <collision>
      <origin
        xyz="0 0 0"
        rpy="0 0 0" />
      <geometry>
        <mesh
          filename="file://$(find robot_bringup)/meshes/fix_cfpipe2tobaselink.STL" />
      </geometry>
    </collision>
  </link>
  <joint
    name="cfpipe2tobaselink"
    type="fixed">
    <origin
      xyz="0 0 0"
      rpy="0 0 0" />
    <parent
      link="base_link" />
    <child
      link="fix_cfpipe2tobaselink" />
    <axis
      xyz="0 0 0" />
  </joint>

  <ros2_control name="leg" type="system">
      <hardware>
          <xacro:if value="$(arg USE_WITH_SIM)">
              <plugin>gz_ros2_control/GazeboSimSystem</plugin>
          </xacro:if>
          <xacro:unless value="$(arg USE_WITH_SIM)">
            <plugin>dynamixel_hardware/DynamixelHardware</plugin>
            <param name="usb_port">/dev/ttyUSB0</param>
            <param name="baud_rate">57600</param>
            <param name="control_mode">position</param>
          </xacro:unless>
      </hardware>
      <joint name="right_hip1">
          <param name="id">1</param>
          <command_interface name="position"/>
          <!-- <command_interface name="velocity"/> -->
          <state_interface name="position"/>
          <state_interface name="velocity"/>
      </joint>
      <joint name="right_hip2">
          <param name="id">2</param>
          <command_interface name="position"/>
          <!-- <command_interface name="velocity"/> -->
          <state_interface name="position"/>
          <state_interface name="velocity"/>
      </joint>
      <joint name="right_knee">
          <param name="id">3</param>
          <command_interface name="position"/>
          <!-- <command_interface name="velocity"/> -->
          <state_interface name="position"/>
          <state_interface name="velocity"/>
      </joint>
      <joint name="left_hip1">
          <param name="id">5</param>
          <command_interface name="position"/>
          <!-- <command_interface name="velocity"/> -->
          <state_interface name="position"/>
          <state_interface name="velocity"/>
      </joint>
      <joint name="left_hip2">
          <param name="id">6</param>
          <command_interface name="position"/>
          <!-- <command_interface name="velocity"/> -->
          <state_interface name="position"/>
          <state_interface name="velocity"/>
      </joint>
      <joint name="left_knee">
          <param name="id">7</param>
          <command_interface name="position"/>
          <!-- <command_interface name="velocity"/> -->
          <state_interface name="position"/>
          <state_interface name="velocity"/>
      </joint>
      <joint name="right_ankle">
          <param name="id">4</param>
          <command_interface name="position"/>
          <!-- <command_interface name="velocity"/> -->
          <state_interface name="position"/>
          <state_interface name="velocity"/>
      </joint>
      <joint name="left_ankle">
          <param name="id">8</param>
          <command_interface name="position"/>
          <!-- <command_interface name="velocity"/> -->
          <state_interface name="position"/>
          <state_interface name="velocity"/>
      </joint>
      <joint name="torso">
          <param name="id">9</param>
          <command_interface name="position"/>
          <!-- <command_interface name="velocity"/> -->
          <state_interface name="position"/>
          <state_interface name="velocity"/>
      </joint>
  </ros2_control>


  <xacro:if value="$(arg USE_WITH_SIM)">
        <gazebo>
            <plugin filename="gz_ros2_control-system" name="gz_ros2_control::GazeboSimROS2ControlPlugin">
                <parameters>$(find robot_bringup)/config/biped.yaml</parameters>
                <ros>
                    <namespace>/$(arg NAMESPACE)</namespace>
                </ros>
            </plugin>
        </gazebo>
  </xacro:if>

</robot>
